Workbook
Name T1.界面类: 功能点类型!$A$2:$A$3
Name T1.界面类st1.新增单个页面: 功能点类型!$A$14:$A$18
Name T1.界面类st2.修改已有页面: 功能点类型!$B$14:$B$18
Name T2.业务逻辑类: 功能点类型!$B$2:$B$3
Name T2.业务逻辑类st1.新增业务逻辑: 功能点类型!$C$14:$C$18
Name T2.业务逻辑类st2.调整业务逻辑: 功能点类型!$D$14:$D$18
Name T3.接口类: 功能点类型!$C$2:$C$5
Name T3.接口类st1.提供方_新增接口: 功能点类型!$E$14:$E$18
Name T3.接口类st1.提供方新增接口: 功能点类型!$E$14:$E$18
Name T3.接口类st2.消费方_新增接口: 功能点类型!$F$14:$F$18
Name T3.接口类st2.消费方新增接口: 功能点类型!$F$14:$F$18
Name T3.接口类st3.修改接口: 功能点类型!$G$14:$G$18
Name T3.接口类st4.纵向接口联调: 功能点类型!$H$14:$H$18
Name T4.流程类: 功能点类型!$D$2:$D$3
Name T4.流程类st1.配置流程_新增流程: 功能点类型!$I$14:$I$18
Name T4.流程类st1.配置流程新增流程: 功能点类型!$I$14:$I$18
Name T4.流程类st2.配置流程_修改流程: 功能点类型!$J$14:$J$18
Name T4.流程类st2.配置流程修改流程: 功能点类型!$J$14:$J$18
Name T5.报表类: 功能点类型!$E$2:$E$4
Name T5.报表类st1.新增报表: 功能点类型!$K$14:$K$18
Name T5.报表类st2.变更报表: 功能点类型!$L$14:$L$18
Name T5.报表类st3.配置报表: 功能点类型!$M$14:$M$18
Name T6.数据处理类: 功能点类型!$F$2:$F$11
Name T6.数据处理类st1.新增导出模板: 功能点类型!$N$14:$N$18
Name T6.数据处理类st10.数据测算: 功能点类型!$W$14:$W$18
Name T6.数据处理类st2.已有导出模板修改: 功能点类型!$O$14:$O$18
Name T6.数据处理类st3.新增导入功能: 功能点类型!$P$14:$P$18
Name T6.数据处理类st4.已有导入功能修改: 功能点类型!$Q$14:$Q$18
Name T6.数据处理类st5.临时取数: 功能点类型!$R$14:$R$18
Name T6.数据处理类st6.数据批量修改: 功能点类型!$S$14:$S$18
Name T6.数据处理类st7.数据配置: 功能点类型!$T$14:$T$18
Name T6.数据处理类st8.数据稽核: 功能点类型!$U$14:$U$18
Name T6.数据处理类st9.数据加工: 功能点类型!$V$14:$V$18
Name T7.实施类: 功能点类型!$G$2:$G$5
Name T7.实施类st1.主机配置: 功能点类型!$X$14:$X$18
Name T7.实施类st2.存储扩容配置: 功能点类型!$Y$14:$Y$18
Name T7.实施类st3.网络策略配置: 功能点类型!$Z$14:$Z$18
Name T7.实施类st4应用部署: 功能点类型!$AA$14:$AA$18
Name T8.推广类: 功能点类型!$H$2:$H$10
Name T8.推广类_仅全国集中系统选: 功能点类型!$H$2:$H$10
Name T8.推广类st.9_网络验证: 功能点类型!$AJ$14:$AJ$18
Name T8.推广类st1.业务差异分析: 功能点类型!$AB$14:$AB$18
Name T8.推广类st2.参数配置: 功能点类型!$AC$14:$AC$18
Name T8.推广类st3.业务端到端测试: 功能点类型!$AD$14:$AD$18
Name T8.推广类st4.软件升级及安装: 功能点类型!$AE$14:$AE$18
Name T8.推广类st5.生产环境压力测试: 功能点类型!$AF$14:$AF$18
Name T8.推广类st6.数据脱敏: 功能点类型!$AG$14:$AG$18
Name T8.推广类st7.数据收集与清理: 功能点类型!$AH$14:$AH$18
Name T8.推广类st8.数据割接: 功能点类型!$AI$14:$AI$18
Name 报表类: 功能点类型!$E$2:$E$11
Name 集成环境复杂性: 功能点类型!$B$24:$B$29
Name 接口类: 功能点类型!$C$2:$C$11
Name 界面类: 功能点类型!$A$2:$A$11
Name 可靠性: 功能点类型!$C$24:$C$29
Name 流程类: 功能点类型!$D$2:$D$11
Name 实施类: 功能点类型!$G$2:$G$11
Name 数据处理类: 功能点类型!$F$2:$F$11
Name 推广类_仅全国集中系统选: 功能点类型!$H$2:$H$11
Name 系统设计容量: 功能点类型!$D$24:$D$29
Name 响应速度: 功能点类型!$A$24:$A$29

Sheet 软件研发项目工作量评估模板
A1: 中国电信2026年宁夏公司AI视频基地平台研发工程 | K1: ="-软件开发工作量评估清单" -> -软件开发工作量评估清单 | T1: 13 | U1: {=IFERROR(INDEX($R$10:$R$463,1+MATCH(,COUNTIF(#REF!,$R$11:$R$463),))&"","")} | V1: {=IF(U1="","",_xlfn.TEXTJOIN(",",1,IF($C$11:$C$463<>"",IF($R$11:$R$463=$U1,$C$11:$C$463,""),"")))} | W1: =IF($U1="","",ROUND(SUMIF($R$11:$R$463,$U1,$N$11:$N$463)*$O$6,2))
A2: 上报单位： | C2: 人工智能业务运营中心 | D2: 研发团队 | E2: 中国电信2026年宁夏公司AI视频基地平台研发工程 | H2: 上报人： | M2: 邮箱： | N2: guoxiaole.nx@chinatelecom.cn | T2: 14 | U2: {=IFERROR(INDEX($R$10:$R$463,1+MATCH(,COUNTIF(U$1:U1,$R$11:$R$463),))&"","")} -> AI视频平台私有化部署 | V2: {=IF(U2="","",_xlfn.TEXTJOIN(",",1,IF($C$11:$C$463<>"",IF($R$11:$R$463=$U2,$C$11:$C$463,""),"")))} -> 环境部署,视频剪辑制作,多人协作,素材管理,项目管理审批,用户管理,运维管理,安全加固测试,OPC创业注册服务,订单管理模块,结算管理与合作分成 | W2: =IF($U2="","",ROUND(SUMIF($R$11:$R$463,$U2,$N$11:$N$463)*$O$6,2)) -> 0
A3: 序 号 | B3: 一级 功能模块 | C3: 二级 功能模块 | D3: 三级 功能模块 | E3: 功能点 说明 | F3: 厂家上报 | K3: 专家评估 | P3: 责任人 | T3: 15 | U3: {=IFERROR(INDEX($R$10:$R$463,1+MATCH(,COUNTIF(U$1:U2,$R$11:$R$463),))&"","")} | V3: {=IF(U3="","",_xlfn.TEXTJOIN(",",1,IF($C$11:$C$463<>"",IF($R$11:$R$463=$U3,$C$11:$C$463,""),"")))} | W3: =IF($U3="","",ROUND(SUMIF($R$11:$R$463,$U3,$N$11:$N$463)*$O$6,2))
B4: 一级 功能模块 | C4: 二级 功能模块 | D4: 三级 功能模块 | E4: 功能点 说明 | F4: 功能点 类别 | G4: 功能点 子类 | H4: 功能复杂度等级 | I4: 评估工作量 (人日) | J4: 预估费用 （万元） | K4: 功能点 类别 | L4: 功能点 子类 | M4: 功能复杂度等级 | N4: 评估工作量 (人日) | O4: 预估费用 （万元） | T4: 16 | U4: {=IFERROR(INDEX($R$10:$R$463,1+MATCH(,COUNTIF(U$1:U3,$R$11:$R$463),))&"","")} | V4: {=IF(U4="","",_xlfn.TEXTJOIN(",",1,IF($C$11:$C$463<>"",IF($R$11:$R$463=$U4,$C$11:$C$463,""),"")))} | W4: =IF($U4="","",ROUND(SUMIF($R$11:$R$463,$U4,$N$11:$N$463)*$O$6,2))
A5: 调整后总工作量（人日）= | T5: 17 | U5: {=IFERROR(INDEX($R$10:$R$463,1+MATCH(,COUNTIF(U$1:U4,$R$11:$R$463),))&"","")} | V5: {=IF(U5="","",_xlfn.TEXTJOIN(",",1,IF($C$11:$C$463<>"",IF($R$11:$R$463=$U5,$C$11:$C$463,""),"")))} | W5: =IF($U5="","",ROUND(SUMIF($R$11:$R$463,$U5,$N$11:$N$463)*$O$6,2))
A6: 0 | B6: 需求流程 管理评估 | C6: 需求分析 | E6: 包括前期需求调研、方案沟通 | I6: 3 | J6: 调整因子 | K6: 响应速度 | L6: 5事务处理响应时间是毫秒级的 | N6: =VLOOKUP($L6,工作量标准!$C:$D,2,0) -> 5 | T6: 18 | U6: {=IFERROR(INDEX($R$10:$R$463,1+MATCH(,COUNTIF(U$1:U5,$R$11:$R$463),))&"","")} | V6: {=IF(U6="","",_xlfn.TEXTJOIN(",",1,IF($C$11:$C$463<>"",IF($R$11:$R$463=$U6,$C$11:$C$463,""),"")))} | W6: =IF($U6="","",ROUND(SUMIF($R$11:$R$463,$U6,$N$11:$N$463)*$O$6,2))
C7: 需求评审 | E7: 需求评审、方案上会评审等 | I7: 2 | K7: 集成环境复杂性 | L7: 4采用了数据库分布式技术 | N7: =VLOOKUP($L7,工作量标准!$C:$D,2,0) -> 4 | T7: 19 | U7: {=IFERROR(INDEX($R$10:$R$463,1+MATCH(,COUNTIF(U$1:U6,$R$11:$R$463),))&"","")} | V7: {=IF(U7="","",_xlfn.TEXTJOIN(",",1,IF($C$11:$C$463<>"",IF($R$11:$R$463=$U7,$C$11:$C$463,""),"")))} | W7: =IF($U7="","",ROUND(SUMIF($R$11:$R$463,$U7,$N$11:$N$463)*$O$6,2))
C8: 测试联调 | E8: 包括需求测试、业务测试、全流程穿测、接口联调等 | I8: =ROUND($I$10*1%,0) -> 0 | K8: 可靠性 | L8: 3应用系统采用了双机热备(数据+应用)措施 | N8: 4 | T8: 20 | U8: {=IFERROR(INDEX($R$10:$R$463,1+MATCH(,COUNTIF(U$1:U7,$R$11:$R$463),))&"","")} | V8: {=IF(U8="","",_xlfn.TEXTJOIN(",",1,IF($C$11:$C$463<>"",IF($R$11:$R$463=$U8,$C$11:$C$463,""),"")))} | W8: =IF($U8="","",ROUND(SUMIF($R$11:$R$463,$U8,$N$11:$N$463)*$O$6,2))
C9: 版本发布 | E9: 版本发布等 | I9: 1 | K9: 系统设计容量 | L9: 3系统设计数据容量1TB至100TB | N9: 4 | T9: 21 | U9: {=IFERROR(INDEX($R$10:$R$463,1+MATCH(,COUNTIF(U$1:U8,$R$11:$R$463),))&"","")} | V9: {=IF(U9="","",_xlfn.TEXTJOIN(",",1,IF($C$11:$C$463<>"",IF($R$11:$R$463=$U9,$C$11:$C$463,""),"")))} | W9: =IF($U9="","",ROUND(SUMIF($R$11:$R$463,$U9,$N$11:$N$463)*$O$6,2))
B10: {=SUM(IFERROR(1/COUNTIFS(B$11:B$4963,"<>",B$11:B$4963,B$11:B$4963),))} -> 1 | C10: {=SUM(IFERROR(1/COUNTIFS(C$11:C$4963,"<>",C$11:C$4963,C$11:C$4963),))} -> 11 | D10: {=SUM(IFERROR(1/COUNTIFS(D$11:D$4963,"<>",D$11:D$4963,D$11:D$4963),))} -> 79 | E10: 未调整总工作量（人日）= | T10: 22 | U10: {=IFERROR(INDEX($R$10:$R$463,1+MATCH(,COUNTIF(U$1:U9,$R$11:$R$463),))&"","")} | V10: {=IF(U10="","",_xlfn.TEXTJOIN(",",1,IF($C$11:$C$463<>"",IF($R$11:$R$463=$U10,$C$11:$C$463,""),"")))} | W10: =IF($U10="","",ROUND(SUMIF($R$11:$R$463,$U10,$N$11:$N$463)*$O$6,2))
A11: 1 | B11: AI视频平台私有化部署 | C11: 环境部署 | D11: 服务器环境规划与搭建 | E11: 服务器环境规划、网络配置 | F11: 实施类 | G11: 主机配置 | H11: C级 | I11: =IFERROR(VLOOKUP(G11,工作量标准!$C:$D,2,0)*IF(IFERROR(FIND("A级",H11),0)>0,1,IF(IFERROR(FIND("B级",H11),0)>0,3,IF(IFERROR(FIND("C级",H11),0)>0,5,IF(IFERROR(FIND("D级",H11),0)>0,8,1)))),"") -> 5 | J11: =IFERROR(ROUND(I11*#REF!/10000,2),"") | K11: 实施类 | L11: 主机配置 | M11: B级 | N11: =IFERROR(VLOOKUP(L11,工作量标准!$C:$D,2,0)*IF(IFERROR(FIND("A级",M11),0)>0,1,IF(IFERROR(FIND("B级",M11),0)>0,3,IF(IFERROR(FIND("C级",M11),0)>0,5,IF(IFERROR(FIND("D级",M11),0)>0,8,1)))),"") -> 3 | Q11: =I11-N11 -> 2 | R11: =IF(ISBLANK(B11),R10,B11) -> AI视频平台私有化部署 | S11: =IF(ISBLANK(C11),S10,C11) -> 环境部署 | T11: 23 | U11: {=IFERROR(INDEX($R$10:$R$463,1+MATCH(,COUNTIF(U$1:U10,$R$11:$R$463),))&"","")} | V11: {=IF(U11="","",_xlfn.TEXTJOIN(",",1,IF($C$11:$C$463<>"",IF($R$11:$R$463=$U11,$C$11:$C$463,""),"")))} | W11: =IF($U11="","",ROUND(SUMIF($R$11:$R$463,$U11,$N$11:$N$463)*$O$6,2))
A12: 2 | D12: Docker/K8s安装 | E12: 容器化环境配置 | F12: 实施类 | G12: 应用部署 | H12: D级 | I12: =IFERROR(VLOOKUP(G12,工作量标准!$C:$D,2,0)*IF(IFERROR(FIND("A级",H12),0)>0,1,IF(IFERROR(FIND("B级",H12),0)>0,3,IF(IFERROR(FIND("C级",H12),0)>0,5,IF(IFERROR(FIND("D级",H12),0)>0,8,1)))),"") -> 8 | J12: =IFERROR(ROUND(I12*#REF!/10000,2),"") | K12: 实施类 | L12: 应用部署 | M12: C级 | N12: =IFERROR(VLOOKUP(L12,工作量标准!$C:$D,2,0)*IF(IFERROR(FIND("A级",M12),0)>0,1,IF(IFERROR(FIND("B级",M12),0)>0,3,IF(IFERROR(FIND("C级",M12),0)>0,5,IF(IFERROR(FIND("D级",M12),0)>0,8,1)))),"") -> 5 | Q12: =I12-N12 -> 3 | R12: =IF(ISBLANK(B12),R11,B12) -> AI视频平台私有化部署 | S12: =IF(ISBLANK(C12),S11,C12) -> 环境部署 | T12: 24 | U12: {=IFERROR(INDEX($R$10:$R$463,1+MATCH(,COUNTIF(U$1:U11,$R$11:$R$463),))&"","")} | V12: {=IF(U12="","",_xlfn.TEXTJOIN(",",1,IF($C$11:$C$463<>"",IF($R$11:$R$463=$U12,$C$11:$C$463,""),"")))} | W12: =IF($U12="","",ROUND(SUMIF($R$11:$R$463,$U12,$N$11:$N$463)*$O$6,2))
A13: 3 | D13: 内网安全规划 | E13: 网络策略配置，防火墙规则 | F13: 实施类 | G13: 网络策略配置 | H13: C级 | I13: =IFERROR(VLOOKUP(G13,工作量标准!$C:$D,2,0)*IF(IFERROR(FIND("A级",H13),0)>0,1,IF(IFERROR(FIND("B级",H13),0)>0,3,IF(IFERROR(FIND("C级",H13),0)>0,5,IF(IFERROR(FIND("D级",H13),0)>0,8,1)))),"") -> 5 | J13: =IFERROR(ROUND(I13*#REF!/10000,2),"") | K13: 实施类 | L13: 网络策略配置 | M13: C级 | N13: =IFERROR(VLOOKUP(L13,工作量标准!$C:$D,2,0)*IF(IFERROR(FIND("A级",M13),0)>0,1,IF(IFERROR(FIND("B级",M13),0)>0,3,IF(IFERROR(FIND("C级",M13),0)>0,5,IF(IFERROR(FIND("D级",M13),0)>0,8,1)))),"") -> 5 | Q13: =I13-N13 -> 0 | R13: =IF(ISBLANK(B13),R12,B13) -> AI视频平台私有化部署 | S13: =IF(ISBLANK(C13),S12,C13) -> 环境部署 | T13: 25 | U13: {=IFERROR(INDEX($R$10:$R$463,1+MATCH(,COUNTIF(U$1:U12,$R$11:$R$463),))&"","")} | V13: {=IF(U13="","",_xlfn.TEXTJOIN(",",1,IF($C$11:$C$463<>"",IF($R$11:$R$463=$U13,$C$11:$C$463,""),"")))} | W13: =IF($U13="","",ROUND(SUMIF($R$11:$R$463,$U13,$N$11:$N$463)*$O$6,2))
A14: 4 | D14: 对象存储配置 | E14: 视频素材存储规划与配置 | F14: 实施类 | G14: 存储扩容配置 | H14: D级 | I14: =IFERROR(VLOOKUP(G14,工作量标准!$C:$D,2,0)*IF(IFERROR(FIND("A级",H14),0)>0,1,IF(IFERROR(FIND("B级",H14),0)>0,3,IF(IFERROR(FIND("C级",H14),0)>0,5,IF(IFERROR(FIND("D级",H14),0)>0,8,1)))),"") -> 8 | J14: =IFERROR(ROUND(I14*#REF!/10000,2),"") | K14: 实施类 | L14: 存储扩容配置 | M14: C级 | N14: =IFERROR(VLOOKUP(L14,工作量标准!$C:$D,2,0)*IF(IFERROR(FIND("A级",M14),0)>0,1,IF(IFERROR(FIND("B级",M14),0)>0,3,IF(IFERROR(FIND("C级",M14),0)>0,5,IF(IFERROR(FIND("D级",M14),0)>0,8,1)))),"") -> 5 | Q14: =I14-N14 -> 3 | R14: =IF(ISBLANK(B14),R13,B14) -> AI视频平台私有化部署 | S14: =IF(ISBLANK(C14),S13,C14) -> 环境部署 | T14: 26 | U14: {=IFERROR(INDEX($R$10:$R$463,1+MATCH(,COUNTIF(U$1:U13,$R$11:$R$463),))&"","")} | V14: {=IF(U14="","",_xlfn.TEXTJOIN(",",1,IF($C$11:$C$463<>"",IF($R$11:$R$463=$U14,$C$11:$C$463,""),"")))} | W14: =IF($U14="","",ROUND(SUMIF($R$11:$R$463,$U14,$N$11:$N$463)*$O$6,2))
A15: 5 | C15: 视频剪辑制作 | D15: 时间轴编辑 | E15: 多轨道时间轴编辑、图层叠加 | F15: 界面类 | G15: 新增单个页面 | H15: D级 | I15: =IFERROR(VLOOKUP(G15,工作量标准!$C:$D,2,0)*IF(IFERROR(FIND("A级",H15),0)>0,1,IF(IFERROR(FIND("B级",H15),0)>0,3,IF(IFERROR(FIND("C级",H15),0)>0,5,IF(IFERROR(FIND("D级",H15),0)>0,8,1)))),"") -> 16 | J15: =IFERROR(ROUND(I15*#REF!/10000,2),"") | K15: 界面类 | L15: 新增单个页面 | M15: C级 | N15: =IFERROR(VLOOKUP(L15,工作量标准!$C:$D,2,0)*IF(IFERROR(FIND("A级",M15),0)>0,1,IF(IFERROR(FIND("B级",M15),0)>0,3,IF(IFERROR(FIND("C级",M15),0)>0,5,IF(IFERROR(FIND("D级",M15),0)>0,8,1)))),"") -> 10 | Q15: =I15-N15 -> 6 | R15: =IF(ISBLANK(B15),R14,B15) -> AI视频平台私有化部署 | S15: =IF(ISBLANK(C15),S14,C15) -> 视频剪辑制作 | T15: 27 | U15: {=IFERROR(INDEX($R$10:$R$463,1+MATCH(,COUNTIF(U$1:U14,$R$11:$R$463),))&"","")} | V15: {=IF(U15="","",_xlfn.TEXTJOIN(",",1,IF($C$11:$C$463<>"",IF($R$11:$R$463=$U15,$C$11:$C$463,""),"")))} | W15: =IF($U15="","",ROUND(SUMIF($R$11:$R$463,$U15,$N$11:$N$463)*$O$6,2))
A16: 6 | D16: 转场特效 | E16: 转场效果、滤镜工具 | F16: 界面类 | G16: 新增单个页面 | H16: D级 | I16: =IFERROR(VLOOKUP(G16,工作量标准!$C:$D,2,0)*IF(IFERROR(FIND("A级",H16),0)>0,1,IF(IFERROR(FIND("B级",H16),0)>0,3,IF(IFERROR(FIND("C级",H16),0)>0,5,IF(IFERROR(FIND("D级",H16),0)>0,8,1)))),"") -> 16 | J16: =IFERROR(ROUND(I16*#REF!/10000,2),"") | K16: 界面类 | L16: 新增单个页面 | M16: C级 | N16: =IFERROR(VLOOKUP(L16,工作量标准!$C:$D,2,0)*IF(IFERROR(FIND("A级",M16),0)>0,1,IF(IFERROR(FIND("B级",M16),0)>0,3,IF(IFERROR(FIND("C级",M16),0)>0,5,IF(IFERROR(FIND("D级",M16),0)>0,8,1)))),"") -> 10 | Q16: =I16-N16 -> 6 | R16: =IF(ISBLANK(B16),R15,B16) -> AI视频平台私有化部署 | S16: =IF(ISBLANK(C16),S15,C16) -> 视频剪辑制作 | T16: 28 | U16: {=IFERROR(INDEX($R$10:$R$463,1+MATCH(,COUNTIF(U$1:U15,$R$11:$R$463),))&"","")} | V16: {=IF(U16="","",_xlfn.TEXTJOIN(",",1,IF($C$11:$C$463<>"",IF($R$11:$R$463=$U16,$C$11:$C$463,""),"")))} | W16: =IF($U16="","",ROUND(SUMIF($R$11:$R$463,$U16,$N$11:$N$463)*$O$6,2))
A17: 7 | D17: FFmpeg转码服务 | E17: 多格式转码、代理文件生成 | F17: 业务逻辑类 | G17: 新增业务逻辑 | H17: D级 | I17: =IFERROR(VLOOKUP(G17,工作量标准!$C:$D,2,0)*IF(IFERROR(FIND("A级",H17),0)>0,1,IF(IFERROR(FIND("B级",H17),0)>0,3,IF(IFERROR(FIND("C级",H17),0)>0,5,IF(IFERROR(FIND("D级",H17),0)>0,8,1)))),"") -> 32 | J17: =IFERROR(ROUND(I17*#REF!/10000,2),"") | K17: 流程类 | L17: 配置流程新增流程 | M17: C级 | N17: =IFERROR(VLOOKUP(L17,工作量标准!$C:$D,2,0)*IF(IFERROR(FIND("A级",M17),0)>0,1,IF(IFERROR(FIND("B级",M17),0)>0,3,IF(IFERROR(FIND("C级",M17),0)>0,5,IF(IFERROR(FIND("D级",M17),0)>0,8,1)))),"") -> 20 | Q17: =I17-N17 -> 12 | R17: =IF(ISBLANK(B17),R16,B17) -> AI视频平台私有化部署 | S17: =IF(ISBLANK(C17),S16,C17) -> 视频剪辑制作 | T17: 29 | U17: {=IFERROR(INDEX($R$10:$R$463,1+MATCH(,COUNTIF(U$1:U16,$R$11:$R$463),))&"","")} | V17: {=IF(U17="","",_xlfn.TEXTJOIN(",",1,IF($C$11:$C$463<>"",IF($R$11:$R$463=$U17,$C$11:$C$463,""),"")))} | W17: =IF($U17="","",ROUND(SUMIF($R$11:$R$463,$U17,$N$11:$N$463)*$O$6,2))
A18: 8 | D18: 导出参数配置 | E18: MP4/MOV/MXF等格式导出 | F18: 业务逻辑类 | G18: 新增业务逻辑 | H18: C级 | I18: =IFERROR(VLOOKUP(G18,工作量标准!$C:$D,2,0)*IF(IFERROR(FIND("A级",H18),0)>0,1,IF(IFERROR(FIND("B级",H18),0)>0,3,IF(IFERROR(FIND("C级",H18),0)>0,5,IF(IFERROR(FIND("D级",H18),0)>0,8,1)))),"") -> 20 | J18: =IFERROR(ROUND(I18*#REF!/10000,2),"") | K18: 流程类 | L18: 配置流程新增流程 | M18: B级 | N18: =IFERROR(VLOOKUP(L18,工作量标准!$C:$D,2,0)*IF(IFERROR(FIND("A级",M18),0)>0,1,IF(IFERROR(FIND("B级",M18),0)>0,3,IF(IFERROR(FIND("C级",M18),0)>0,5,IF(IFERROR(FIND("D级",M18),0)>0,8,1)))),"") -> 12 | Q18: =I18-N18 -> 8 | R18: =IF(ISBLANK(B18),R17,B18) -> AI视频平台私有化部署 | S18: =IF(ISBLANK(C18),S17,C18) -> 视频剪辑制作 | T18: 30 | U18: {=IFERROR(INDEX($R$10:$R$463,1+MATCH(,COUNTIF(U$1:U17,$R$11:$R$463),))&"","")} | V18: {=IF(U18="","",_xlfn.TEXTJOIN(",",1,IF($C$11:$C$463<>"",IF($R$11:$R$463=$U18,$C$11:$C$463,""),"")))} | W18: =IF($U18="","",ROUND(SUMIF($R$11:$R$463,$U18,$N$11:$N$463)*$O$6,2))
A19: 9 | D19: 实时预览 | E19: 低分辨率代理文件预览 | F19: 业务逻辑类 | G19: 新增业务逻辑 | H19: C级 | I19: =IFERROR(VLOOKUP(G19,工作量标准!$C:$D,2,0)*IF(IFERROR(FIND("A级",H19),0)>0,1,IF(IFERROR(FIND("B级",H19),0)>0,3,IF(IFERROR(FIND("C级",H19),0)>0,5,IF(IFERROR(FIND("D级",H19),0)>0,8,1)))),"") -> 20 | J19: =IFERROR(ROUND(I19*#REF!/10000,2),"") | K19: 流程类 | L19: 配置流程新增流程 | M19: B级 | N19: =IFERROR(VLOOKUP(L19,工作量标准!$C:$D,2,0)*IF(IFERROR(FIND("A级",M19),0)>0,1,IF(IFERROR(FIND("B级",M19),0)>0,3,IF(IFERROR(FIND("C级",M19),0)>0,5,IF(IFERROR(FIND("D级",M19),0)>0,8,1)))),"") -> 12 | Q19: =I19-N19 -> 8 | R19: =IF(ISBLANK(B19),R18,B19) -> AI视频平台私有化部署 | S19: =IF(ISBLANK(C19),S18,C19) -> 视频剪辑制作
A20: 10 | C20: 多人协作 | D20: 在线状态同步 | E20: 多人实时在线状态显示 | F20: 接口类 | G20: 提供方新增接口 | H20: D级 | I20: =IFERROR(VLOOKUP(G20,工作量标准!$C:$D,2,0)*IF(IFERROR(FIND("A级",H20),0)>0,1,IF(IFERROR(FIND("B级",H20),0)>0,3,IF(IFERROR(FIND("C级",H20),0)>0,5,IF(IFERROR(FIND("D级",H20),0)>0,8,1)))),"") -> 32 | J20: =IFERROR(ROUND(I20*#REF!/10000,2),"") | K20: 流程类 | L20: 配置流程新增流程 | M20: B级 | N20: =IFERROR(VLOOKUP(L20,工作量标准!$C:$D,2,0)*IF(IFERROR(FIND("A级",M20),0)>0,1,IF(IFERROR(FIND("B级",M20),0)>0,3,IF(IFERROR(FIND("C级",M20),0)>0,5,IF(IFERROR(FIND("D级",M20),0)>0,8,1)))),"") -> 12 | O20: =IFERROR(ROUND(N20*#REF!/10000,2),"") | Q20: =I20-N20 -> 20 | R20: =IF(ISBLANK(B20),R19,B20) -> AI视频平台私有化部署 | S20: =IF(ISBLANK(C20),S19,C20) -> 多人协作
A21: 11 | D21: 操作同步 | E21: 实时操作广播与同步 | F21: 业务逻辑类 | G21: 新增业务逻辑 | H21: D级 | I21: =IFERROR(VLOOKUP(G21,工作量标准!$C:$D,2,0)*IF(IFERROR(FIND("A级",H21),0)>0,1,IF(IFERROR(FIND("B级",H21),0)>0,3,IF(IFERROR(FIND("C级",H21),0)>0,5,IF(IFERROR(FIND("D级",H21),0)>0,8,1)))),"") -> 32 | J21: =IFERROR(ROUND(I21*#REF!/10000,2),"") | K21: 流程类 | L21: 配置流程新增流程 | M21: C级 | N21: =IFERROR(VLOOKUP(L21,工作量标准!$C:$D,2,0)*IF(IFERROR(FIND("A级",M21),0)>0,1,IF(IFERROR(FIND("B级",M21),0)>0,3,IF(IFERROR(FIND("C级",M21),0)>0,5,IF(IFERROR(FIND("D级",M21),0)>0,8,1)))),"") -> 20 | O21: =IFERROR(ROUND(N21*#REF!/10000,2),"") | Q21: =I21-N21 -> 12 | R21: =IF(ISBLANK(B21),R20,B21) -> AI视频平台私有化部署 | S21: =IF(ISBLANK(C21),S20,C21) -> 多人协作
A22: 12 | D22: 历史版本管理 | E22: 版本记录、回滚能力 | F22: 业务逻辑类 | G22: 新增业务逻辑 | H22: C级 | I22: =IFERROR(VLOOKUP(G22,工作量标准!$C:$D,2,0)*IF(IFERROR(FIND("A级",H22),0)>0,1,IF(IFERROR(FIND("B级",H22),0)>0,3,IF(IFERROR(FIND("C级",H22),0)>0,5,IF(IFERROR(FIND("D级",H22),0)>0,8,1)))),"") -> 20 | J22: =IFERROR(ROUND(I22*#REF!/10000,2),"") | K22: 流程类 | L22: 配置流程新增流程 | M22: C级 | N22: =IFERROR(VLOOKUP(L22,工作量标准!$C:$D,2,0)*IF(IFERROR(FIND("A级",M22),0)>0,1,IF(IFERROR(FIND("B级",M22),0)>0,3,IF(IFERROR(FIND("C级",M22),0)>0,5,IF(IFERROR(FIND("D级",M22),0)>0,8,1)))),"") -> 20 | O22: =IFERROR(ROUND(N22*#REF!/10000,2),"") | Q22: =I22-N22 -> 0 | R22: =IF(ISBLANK(B22),R21,B22) -> AI视频平台私有化部署 | S22: =IF(ISBLANK(C22),S21,C22) -> 多人协作
A23: 13 | D23: 锁定机制 | E23: 编辑锁定、冲突检测 | F23: 业务逻辑类 | G23: 新增业务逻辑 | H23: B级 | I23: =IFERROR(VLOOKUP(G23,工作量标准!$C:$D,2,0)*IF(IFERROR(FIND("A级",H23),0)>0,1,IF(IFERROR(FIND("B级",H23),0)>0,3,IF(IFERROR(FIND("C级",H23),0)>0,5,IF(IFERROR(FIND("D级",H23),0)>0,8,1)))),"") -> 12 | J23: =IFERROR(ROUND(I23*#REF!/10000,2),"") | K23: 流程类 | L23: 配置流程新增流程 | M23: B级 | N23: =IFERROR(VLOOKUP(L23,工作量标准!$C:$D,2,0)*IF(IFERROR(FIND("A级",M23),0)>0,1,IF(IFERROR(FIND("B级",M23),0)>0,3,IF(IFERROR(FIND("C级",M23),0)>0,5,IF(IFERROR(FIND("D级",M23),0)>0,8,1)))),"") -> 12 | O23: =IFERROR(ROUND(N23*#REF!/10000,2),"") | Q23: =I23-N23 -> 0 | R23: =IF(ISBLANK(B23),R22,B23) -> AI视频平台私有化部署 | S23: =IF(ISBLANK(C23),S22,C23) -> 多人协作
A24: 14 | D24: 时间轴批注 | E24: 精准时间点批注与讨论 | F24: 界面类 | G24: 新增单个页面 | H24: C级 | I24: =IFERROR(VLOOKUP(G24,工作量标准!$C:$D,2,0)*IF(IFERROR(FIND("A级",H24),0)>0,1,IF(IFERROR(FIND("B级",H24),0)>0,3,IF(IFERROR(FIND("C级",H24),0)>0,5,IF(IFERROR(FIND("D级",H24),0)>0,8,1)))),"") -> 10 | J24: =IFERROR(ROUND(I24*#REF!/10000,2),"") | K24: 界面类 | L24: 新增单个页面 | M24: C级 | N24: =IFERROR(VLOOKUP(L24,工作量标准!$C:$D,2,0)*IF(IFERROR(FIND("A级",M24),0)>0,1,IF(IFERROR(FIND("B级",M24),0)>0,3,IF(IFERROR(FIND("C级",M24),0)>0,5,IF(IFERROR(FIND("D级",M24),0)>0,8,1)))),"") -> 10 | O24: =IFERROR(ROUND(N24*#REF!/10000,2),"") | Q24: =I24-N24 -> 0 | R24: =IF(ISBLANK(B24),R23,B24) -> AI视频平台私有化部署 | S24: =IF(ISBLANK(C24),S23,C24) -> 多人协作
A25: 15 | C25: 素材管理 | D25: 大文件上传 | E25: 分片上传、断点续传 | F25: 业务逻辑类 | G25: 新增业务逻辑 | H25: C级 | I25: =IFERROR(VLOOKUP(G25,工作量标准!$C:$D,2,0)*IF(IFERROR(FIND("A级",H25),0)>0,1,IF(IFERROR(FIND("B级",H25),0)>0,3,IF(IFERROR(FIND("C级",H25),0)>0,5,IF(IFERROR(FIND("D级",H25),0)>0,8,1)))),"") -> 20 | J25: =IFERROR(ROUND(I25*#REF!/10000,2),"") | K25: 流程类 | L25: 配置流程新增流程 | M25: B级 | N25: =IFERROR(VLOOKUP(L25,工作量标准!$C:$D,2,0)*IF(IFERROR(FIND("A级",M25),0)>0,1,IF(IFERROR(FIND("B级",M25),0)>0,3,IF(IFERROR(FIND("C级",M25),0)>0,5,IF(IFERROR(FIND("D级",M25),0)>0,8,1)))),"") -> 12 | O25: =IFERROR(ROUND(N25*#REF!/10000,2),"") | Q25: =I25-N25 -> 8 | R25: =IF(ISBLANK(B25),R24,B25) -> AI视频平台私有化部署 | S25: =IF(ISBLANK(C25),S24,C25) -> 素材管理
A26: 16 | D26: 缩略图生成 | E26: 视频缩略图自动生成 | F26: 业务逻辑类 | G26: 新增业务逻辑 | H26: B级 | I26: =IFERROR(VLOOKUP(G26,工作量标准!$C:$D,2,0)*IF(IFERROR(FIND("A级",H26),0)>0,1,IF(IFERROR(FIND("B级",H26),0)>0,3,IF(IFERROR(FIND("C级",H26),0)>0,5,IF(IFERROR(FIND("D级",H26),0)>0,8,1)))),"") -> 12 | J26: =IFERROR(ROUND(I26*#REF!/10000,2),"") | K26: 流程类 | L26: 配置流程新增流程 | M26: B级 | N26: =IFERROR(VLOOKUP(L26,工作量标准!$C:$D,2,0)*IF(IFERROR(FIND("A级",M26),0)>0,1,IF(IFERROR(FIND("B级",M26),0)>0,3,IF(IFERROR(FIND("C级",M26),0)>0,5,IF(IFERROR(FIND("D级",M26),0)>0,8,1)))),"") -> 12 | O26: =IFERROR(ROUND(N26*#REF!/10000,2),"") | Q26: =I26-N26 -> 0 | R26: =IF(ISBLANK(B26),R25,B26) -> AI视频平台私有化部署 | S26: =IF(ISBLANK(C26),S25,C26) -> 素材管理
A27: 17 | D27: 搜索引擎 | E27: 全文检索、标签搜索 | F27: 界面类 | G27: 新增单个页面 | H27: C级 | I27: =IFERROR(VLOOKUP(G27,工作量标准!$C:$D,2,0)*IF(IFERROR(FIND("A级",H27),0)>0,1,IF(IFERROR(FIND("B级",H27),0)>0,3,IF(IFERROR(FIND("C级",H27),0)>0,5,IF(IFERROR(FIND("D级",H27),0)>0,8,1)))),"") -> 10 | J27: =IFERROR(ROUND(I27*#REF!/10000,2),"") | K27: 界面类 | L27: 新增单个页面 | M27: C级 | N27: =IFERROR(VLOOKUP(L27,工作量标准!$C:$D,2,0)*IF(IFERROR(FIND("A级",M27),0)>0,1,IF(IFERROR(FIND("B级",M27),0)>0,3,IF(IFERROR(FIND("C级",M27),0)>0,5,IF(IFERROR(FIND("D级",M27),0)>0,8,1)))),"") -> 10 | O27: =IFERROR(ROUND(N27*#REF!/10000,2),"") | Q27: =I27-N27 -> 0 | R27: =IF(ISBLANK(B27),R26,B27) -> AI视频平台私有化部署 | S27: =IF(ISBLANK(C27),S26,C27) -> 素材管理
A28: 18 | D28: 版本管理 | E28: 素材版本历史记录 | F28: 业务逻辑类 | G28: 新增业务逻辑 | H28: B级 | I28: =IFERROR(VLOOKUP(G28,工作量标准!$C:$D,2,0)*IF(IFERROR(FIND("A级",H28),0)>0,1,IF(IFERROR(FIND("B级",H28),0)>0,3,IF(IFERROR(FIND("C级",H28),0)>0,5,IF(IFERROR(FIND("D级",H28),0)>0,8,1)))),"") -> 12 | J28: =IFERROR(ROUND(I28*#REF!/10000,2),"") | K28: 流程类 | L28: 配置流程新增流程 | M28: B级 | N28: =IFERROR(VLOOKUP(L28,工作量标准!$C:$D,2,0)*IF(IFERROR(FIND("A级",M28),0)>0,1,IF(IFERROR(FIND("B级",M28),0)>0,3,IF(IFERROR(FIND("C级",M28),0)>0,5,IF(IFERROR(FIND("D级",M28),0)>0,8,1)))),"") -> 12 | O28: =IFERROR(ROUND(N28*#REF!/10000,2),"") | Q28: =I28-N28 -> 0 | R28: =IF(ISBLANK(B28),R27,B28) -> AI视频平台私有化部署 | S28: =IF(ISBLANK(C28),S27,C28) -> 素材管理
A29: 19 | D29: 标签分类 | E29: 自定义元数据、分类管理 | F29: 界面类 | G29: 新增单个页面 | H29: C级 | I29: =IFERROR(VLOOKUP(G29,工作量标准!$C:$D,2,0)*IF(IFERROR(FIND("A级",H29),0)>0,1,IF(IFERROR(FIND("B级",H29),0)>0,3,IF(IFERROR(FIND("C级",H29),0)>0,5,IF(IFERROR(FIND("D级",H29),0)>0,8,1)))),"") -> 10 | J29: =IFERROR(ROUND(I29*#REF!/10000,2),"") | K29: 界面类 | L29: 新增单个页面 | M29: C级 | N29: =IFERROR(VLOOKUP(L29,工作量标准!$C:$D,2,0)*IF(IFERROR(FIND("A级",M29),0)>0,1,IF(IFERROR(FIND("B级",M29),0)>0,3,IF(IFERROR(FIND("C级",M29),0)>0,5,IF(IFERROR(FIND("D级",M29),0)>0,8,1)))),"") -> 10 | O29: =IFERROR(ROUND(N29*#REF!/10000,2),"") | Q29: =I29-N29 -> 0 | R29: =IF(ISBLANK(B29),R28,B29) -> AI视频平台私有化部署 | S29: =IF(ISBLANK(C29),S28,C29) -> 素材管理
A30: 20 | C30: 项目管理审批 | D30: 项目基本管理 | E30: 项目创建、成员管理、任务分配 | F30: 界面类 | G30: 新增单个页面 | H30: C级 | I30: =IFERROR(VLOOKUP(G30,工作量标准!$C:$D,2,0)*IF(IFERROR(FIND("A级",H30),0)>0,1,IF(IFERROR(FIND("B级",H30),0)>0,3,IF(IFERROR(FIND("C级",H30),0)>0,5,IF(IFERROR(FIND("D级",H30),0)>0,8,1)))),"") -> 10 | J30: =IFERROR(ROUND(I30*#REF!/10000,2),"") | K30: 界面类 | L30: 新增单个页面 | M30: C级 | N30: =IFERROR(VLOOKUP(L30,工作量标准!$C:$D,2,0)*IF(IFERROR(FIND("A级",M30),0)>0,1,IF(IFERROR(FIND("B级",M30),0)>0,3,IF(IFERROR(FIND("C级",M30),0)>0,5,IF(IFERROR(FIND("D级",M30),0)>0,8,1)))),"") -> 10 | O30: =IFERROR(ROUND(N30*#REF!/10000,2),"") | Q30: =I30-N30 -> 0 | R30: =IF(ISBLANK(B30),R29,B30) -> AI视频平台私有化部署 | S30: =IF(ISBLANK(C30),S29,C30) -> 项目管理审批
A31: 21 | D31: 多级审批 | E31: 初审、复审、终审配置 | F31: 流程类 | G31: 配置流程新增流程 | H31: D级 | I31: =IFERROR(VLOOKUP(G31,工作量标准!$C:$D,2,0)*IF(IFERROR(FIND("A级",H31),0)>0,1,IF(IFERROR(FIND("B级",H31),0)>0,3,IF(IFERROR(FIND("C级",H31),0)>0,5,IF(IFERROR(FIND("D级",H31),0)>0,8,1)))),"") -> 32 | J31: =IFERROR(ROUND(I31*#REF!/10000,2),"") | K31: 流程类 | L31: 配置流程新增流程 | M31: C级 | N31: =IFERROR(VLOOKUP(L31,工作量标准!$C:$D,2,0)*IF(IFERROR(FIND("A级",M31),0)>0,1,IF(IFERROR(FIND("B级",M31),0)>0,3,IF(IFERROR(FIND("C级",M31),0)>0,5,IF(IFERROR(FIND("D级",M31),0)>0,8,1)))),"") -> 20 | O31: =IFERROR(ROUND(N31*#REF!/10000,2),"") | Q31: =I31-N31 -> 12 | R31: =IF(ISBLANK(B31),R30,B31) -> AI视频平台私有化部署 | S31: =IF(ISBLANK(C31),S30,C31) -> 项目管理审批
A32: 22 | D32: 甘特图 | E32: 项目进度甘特图展示 | F32: 界面类 | G32: 新增单个页面 | H32: D级 | I32: =IFERROR(VLOOKUP(G32,工作量标准!$C:$D,2,0)*IF(IFERROR(FIND("A级",H32),0)>0,1,IF(IFERROR(FIND("B级",H32),0)>0,3,IF(IFERROR(FIND("C级",H32),0)>0,5,IF(IFERROR(FIND("D级",H32),0)>0,8,1)))),"") -> 16 | J32: =IFERROR(ROUND(I32*#REF!/10000,2),"") | K32: 界面类 | L32: 新增单个页面 | M32: C级 | N32: =IFERROR(VLOOKUP(L32,工作量标准!$C:$D,2,0)*IF(IFERROR(FIND("A级",M32),0)>0,1,IF(IFERROR(FIND("B级",M32),0)>0,3,IF(IFERROR(FIND("C级",M32),0)>0,5,IF(IFERROR(FIND("D级",M32),0)>0,8,1)))),"") -> 10 | O32: =IFERROR(ROUND(N32*#REF!/10000,2),"") | Q32: =I32-N32 -> 6 | R32: =IF(ISBLANK(B32),R31,B32) -> AI视频平台私有化部署 | S32: =IF(ISBLANK(C32),S31,C32) -> 项目管理审批
A33: 23 | D33: 多渠道推送 | E33: 邮件/企业微信通知推送 | F33: 接口类 | G33: 提供方新增接口 | H33: C级 | I33: =IFERROR(VLOOKUP(G33,工作量标准!$C:$D,2,0)*IF(IFERROR(FIND("A级",H33),0)>0,1,IF(IFERROR(FIND("B级",H33),0)>0,3,IF(IFERROR(FIND("C级",H33),0)>0,5,IF(IFERROR(FIND("D级",H33),0)>0,8,1)))),"") -> 20 | J33: =IFERROR(ROUND(I33*#REF!/10000,2),"") | K33: 接口类 | L33: 提供方新增接口 | M33: C级 | N33: =IFERROR(VLOOKUP(L33,工作量标准!$C:$D,2,0)*IF(IFERROR(FIND("A级",M33),0)>0,1,IF(IFERROR(FIND("B级",M33),0)>0,3,IF(IFERROR(FIND("C级",M33),0)>0,5,IF(IFERROR(FIND("D级",M33),0)>0,8,1)))),"") -> 20 | O33: =IFERROR(ROUND(N33*#REF!/10000,2),"") | Q33: =I33-N33 -> 0 | R33: =IF(ISBLANK(B33),R32,B33) -> AI视频平台私有化部署 | S33: =IF(ISBLANK(C33),S32,C33) -> 项目管理审批
A34: 24 | C34: 用户管理 | D34: 单点登录 | E34: 对接企业SSO/LDAP/AD | F34: 接口类 | G34: 消费方新增接口 | H34: D级 | I34: =IFERROR(VLOOKUP(G34,工作量标准!$C:$D,2,0)*IF(IFERROR(FIND("A级",H34),0)>0,1,IF(IFERROR(FIND("B级",H34),0)>0,3,IF(IFERROR(FIND("C级",H34),0)>0,5,IF(IFERROR(FIND("D级",H34),0)>0,8,1)))),"") -> 16 | J34: =IFERROR(ROUND(I34*#REF!/10000,2),"") | K34: 接口类 | L34: 消费方新增接口 | M34: C级 | N34: =IFERROR(VLOOKUP(L34,工作量标准!$C:$D,2,0)*IF(IFERROR(FIND("A级",M34),0)>0,1,IF(IFERROR(FIND("B级",M34),0)>0,3,IF(IFERROR(FIND("C级",M34),0)>0,5,IF(IFERROR(FIND("D级",M34),0)>0,8,1)))),"") -> 10 | O34: =IFERROR(ROUND(N34*#REF!/10000,2),"") | Q34: =I34-N34 -> 6 | R34: =IF(ISBLANK(B34),R33,B34) -> AI视频平台私有化部署 | S34: =IF(ISBLANK(C34),S33,C34) -> 用户管理
A35: 25 | D35: 多级组织 | E35: 多级组织架构管理 | F35: 界面类 | G35: 新增单个页面 | H35: C级 | I35: =IFERROR(VLOOKUP(G35,工作量标准!$C:$D,2,0)*IF(IFERROR(FIND("A级",H35),0)>0,1,IF(IFERROR(FIND("B级",H35),0)>0,3,IF(IFERROR(FIND("C级",H35),0)>0,5,IF(IFERROR(FIND("D级",H35),0)>0,8,1)))),"") -> 10 | J35: =IFERROR(ROUND(I35*#REF!/10000,2),"") | K35: 界面类 | L35: 新增单个页面 | M35: B级 | N35: =IFERROR(VLOOKUP(L35,工作量标准!$C:$D,2,0)*IF(IFERROR(FIND("A级",M35),0)>0,1,IF(IFERROR(FIND("B级",M35),0)>0,3,IF(IFERROR(FIND("C级",M35),0)>0,5,IF(IFERROR(FIND("D级",M35),0)>0,8,1)))),"") -> 6 | O35: =IFERROR(ROUND(N35*#REF!/10000,2),"") | Q35: =I35-N35 -> 4 | R35: =IF(ISBLANK(B35),R34,B35) -> AI视频平台私有化部署 | S35: =IF(ISBLANK(C35),S34,C35) -> 用户管理
A36: 26 | D36: 角色权限 | E36: 项目/素材/功能级权限配置 | F36: 业务逻辑类 | G36: 新增业务逻辑 | H36: D级 | I36: =IFERROR(VLOOKUP(G36,工作量标准!$C:$D,2,0)*IF(IFERROR(FIND("A级",H36),0)>0,1,IF(IFERROR(FIND("B级",H36),0)>0,3,IF(IFERROR(FIND("C级",H36),0)>0,5,IF(IFERROR(FIND("D级",H36),0)>0,8,1)))),"") -> 32 | J36: =IFERROR(ROUND(I36*#REF!/10000,2),"") | K36: 流程类 | L36: 配置流程新增流程 | M36: C级 | N36: =IFERROR(VLOOKUP(L36,工作量标准!$C:$D,2,0)*IF(IFERROR(FIND("A级",M36),0)>0,1,IF(IFERROR(FIND("B级",M36),0)>0,3,IF(IFERROR(FIND("C级",M36),0)>0,5,IF(IFERROR(FIND("D级",M36),0)>0,8,1)))),"") -> 20 | O36: =IFERROR(ROUND(N36*#REF!/10000,2),"") | Q36: =I36-N36 -> 12 | R36: =IF(ISBLANK(B36),R35,B36) -> AI视频平台私有化部署 | S36: =IF(ISBLANK(C36),S35,C36) -> 用户管理
A37: 27 | D37: 批量授权 | E37: 批量赋权、角色模板 | F37: 界面类 | G37: 新增单个页面 | H37: B级 | I37: =IFERROR(VLOOKUP(G37,工作量标准!$C:$D,2,0)*IF(IFERROR(FIND("A级",H37),0)>0,1,IF(IFERROR(FIND("B级",H37),0)>0,3,IF(IFERROR(FIND("C级",H37),0)>0,5,IF(IFERROR(FIND("D级",H37),0)>0,8,1)))),"") -> 6 | J37: =IFERROR(ROUND(I37*#REF!/10000,2),"") | K37: 界面类 | L37: 新增单个页面 | M37: B级 | N37: =IFERROR(VLOOKUP(L37,工作量标准!$C:$D,2,0)*IF(IFERROR(FIND("A级",M37),0)>0,1,IF(IFERROR(FIND("B级",M37),0)>0,3,IF(IFERROR(FIND("C级",M37),0)>0,5,IF(IFERROR(FIND("D级",M37),0)>0,8,1)))),"") -> 6 | O37: =IFERROR(ROUND(N37*#REF!/10000,2),"") | Q37: =I37-N37 -> 0 | R37: =IF(ISBLANK(B37),R36,B37) -> AI视频平台私有化部署 | S37: =IF(ISBLANK(C37),S36,C37) -> 用户管理
A38: 28 | C38: 运维管理 | D38: 资源监控 | E38: CPU/内存/存储/网络监控 | F38: 界面类 | G38: 新增单个页面 | H38: D级 | I38: =IFERROR(VLOOKUP(G38,工作量标准!$C:$D,2,0)*IF(IFERROR(FIND("A级",H38),0)>0,1,IF(IFERROR(FIND("B级",H38),0)>0,3,IF(IFERROR(FIND("C级",H38),0)>0,5,IF(IFERROR(FIND("D级",H38),0)>0,8,1)))),"") -> 16 | J38: =IFERROR(ROUND(I38*#REF!/10000,2),"") | K38: 界面类 | L38: 新增单个页面 | M38: C级 | N38: =IFERROR(VLOOKUP(L38,工作量标准!$C:$D,2,0)*IF(IFERROR(FIND("A级",M38),0)>0,1,IF(IFERROR(FIND("B级",M38),0)>0,3,IF(IFERROR(FIND("C级",M38),0)>0,5,IF(IFERROR(FIND("D级",M38),0)>0,8,1)))),"") -> 10 | O38: =IFERROR(ROUND(N38*#REF!/10000,2),"") | Q38: =I38-N38 -> 6 | R38: =IF(ISBLANK(B38),R37,B38) -> AI视频平台私有化部署 | S38: =IF(ISBLANK(C38),S37,C38) -> 运维管理
A39: 29 | D39: 告警规则 | E39: 阈值告警、邮件推送 | F39: 业务逻辑类 | G39: 新增业务逻辑 | H39: C级 | I39: =IFERROR(VLOOKUP(G39,工作量标准!$C:$D,2,0)*IF(IFERROR(FIND("A级",H39),0)>0,1,IF(IFERROR(FIND("B级",H39),0)>0,3,IF(IFERROR(FIND("C级",H39),0)>0,5,IF(IFERROR(FIND("D级",H39),0)>0,8,1)))),"") -> 20 | J39: =IFERROR(ROUND(I39*#REF!/10000,2),"") | K39: 流程类 | L39: 配置流程新增流程 | M39: B级 | N39: =IFERROR(VLOOKUP(L39,工作量标准!$C:$D,2,0)*IF(IFERROR(FIND("A级",M39),0)>0,1,IF(IFERROR(FIND("B级",M39),0)>0,3,IF(IFERROR(FIND("C级",M39),0)>0,5,IF(IFERROR(FIND("D级",M39),0)>0,8,1)))),"") -> 12 | O39: =IFERROR(ROUND(N39*#REF!/10000,2),"") | Q39: =I39-N39 -> 8 | R39: =IF(ISBLANK(B39),R38,B39) -> AI视频平台私有化部署 | S39: =IF(ISBLANK(C39),S38,C39) -> 运维管理
A40: 30 | D40: 操作日志 | E40: 完整操作日志、安全审计 | F40: 业务逻辑类 | G40: 新增业务逻辑 | H40: C级 | I40: =IFERROR(VLOOKUP(G40,工作量标准!$C:$D,2,0)*IF(IFERROR(FIND("A级",H40),0)>0,1,IF(IFERROR(FIND("B级",H40),0)>0,3,IF(IFERROR(FIND("C级",H40),0)>0,5,IF(IFERROR(FIND("D级",H40),0)>0,8,1)))),"") -> 20 | J40: =IFERROR(ROUND(I40*#REF!/10000,2),"") | K40: 数据处理类 | L40: 数据稽核 | M40: B级 | N40: =IFERROR(VLOOKUP(L40,工作量标准!$C:$D,2,0)*IF(IFERROR(FIND("A级",M40),0)>0,1,IF(IFERROR(FIND("B级",M40),0)>0,3,IF(IFERROR(FIND("C级",M40),0)>0,5,IF(IFERROR(FIND("D级",M40),0)>0,8,1)))),"") -> 6 | O40: =IFERROR(ROUND(N40*#REF!/10000,2),"") | Q40: =I40-N40 -> 14 | R40: =IF(ISBLANK(B40),R39,B40) -> AI视频平台私有化部署 | S40: =IF(ISBLANK(C40),S39,C40) -> 运维管理
...

Sheet 工作量评估
A1: =$A$25 -> xm | J1: -审议结果 | N1: =TEXT(NOW(),"YYYY年MM月DD日") -> 2026年08月19日 | O1: 长途传输局1楼会议室 | P1: 一级功能模块
A2: 功能点类别 | C2: 需求数量 | D2: 厂家报工作量（人日） | E2: 核实工作量（人日） | F2: 预估不含税单价（人日/元） | J2: 预估费用（万元） | P2: {=INDEX($B$27:$B$236,1+MATCH(,COUNTIF(P$1:P1,B$28:B$236),))&""}
A3: 界面类 | C3: =COUNTIFS($F$24:$F$3922,$A3)-COUNTIFS($F$24:$F$3922,$A3,$M$24:$M$3922,"*不通过*") -> 2 | D3: =SUMIFS($I$21:$I$3922,$F$21:$F$3922,$A3)-SUMIFS($I$21:$I$3922,$F$21:$F$3922,$A3,$M$21:$M$3922,"*不通过*") -> 13 | E3: 2378 | F3: 754.717 | J3: 179.48
A4: 业务逻辑类 | C4: =COUNTIFS($F$24:$F$3922,$A4)-COUNTIFS($F$24:$F$3922,$A4,$M$24:$M$3922,"*不通过*") -> 2 | D4: =SUMIFS($I$21:$I$3922,$F$21:$F$3922,$A4)-SUMIFS($I$21:$I$3922,$F$21:$F$3922,$A4,$M$21:$M$3922,"*不通过*") -> 60 | E4: 0 | F4: 377.359 | J4: 0
A5: 接口类 | C5: =COUNTIFS($F$24:$F$3922,$A5)-COUNTIFS($F$24:$F$3922,$A5,$M$24:$M$3922,"*不通过*") -> 4 | D5: =SUMIFS($I$21:$I$3922,$F$21:$F$3922,$A5)-SUMIFS($I$21:$I$3922,$F$21:$F$3922,$A5,$M$21:$M$3922,"*不通过*") -> 38 | E5: 0 | F5: 188.68 | J5: 0
A6: 流程类 | C6: =COUNTIFS($F$24:$F$3922,$A6)-COUNTIFS($F$24:$F$3922,$A6,$M$24:$M$3922,"*不通过*") -> 4 | D6: =SUMIFS($I$21:$I$3922,$F$21:$F$3922,$A6)-SUMIFS($I$21:$I$3922,$F$21:$F$3922,$A6,$M$21:$M$3922,"*不通过*") -> 63
A7: 报表类 | C7: =COUNTIFS($F$24:$F$3922,$A7)-COUNTIFS($F$24:$F$3922,$A7,$M$24:$M$3922,"*不通过*") -> 3 | D7: =SUMIFS($I$21:$I$3922,$F$21:$F$3922,$A7)-SUMIFS($I$21:$I$3922,$F$21:$F$3922,$A7,$M$21:$M$3922,"*不通过*") -> 12
A8: 数据处理类 | C8: =COUNTIFS($F$24:$F$3922,$A8)-COUNTIFS($F$24:$F$3922,$A8,$M$24:$M$3922,"*不通过*") -> 10 | D8: =SUMIFS($I$21:$I$3922,$F$21:$F$3922,$A8)-SUMIFS($I$21:$I$3922,$F$21:$F$3922,$A8,$M$21:$M$3922,"*不通过*") -> 90
A9: 实施类 | C9: =COUNTIFS($F$24:$F$3922,$A9)-COUNTIFS($F$24:$F$3922,$A9,$M$24:$M$3922,"*不通过*") -> 4 | D9: =SUMIFS($I$21:$I$3922,$F$21:$F$3922,$A9)-SUMIFS($I$21:$I$3922,$F$21:$F$3922,$A9,$M$21:$M$3922,"*不通过*") -> 22
A10: 合计 | C10: 43 | D10: 5313 | E10: 2378 | F10: 预估费用取整 | J10: =$L$28 -> 5.28
A11: 会议时间： | D11: =N1 -> 2026年08月19日 | F11: 会议地点： | J11: =O1 -> 长途传输局1楼会议室
A12: =" `召开总经理办公会对：【2022年中国电信宁夏公司IT系统BMO拉通数字化转型竞赛客服检查等43项软件开发项目】进行了审议，共【43】个需求，评审通过【43】个需求." -> `召开总经理办公会对：【2022年中国电信宁夏公司IT系统BMO拉通数字化转型竞赛客服检查等43项软件开发项目】进行了审议，共【43】个需求，评审通过【43】个需求.
A13: 需求提出部门：云网运营事业部【19】项【106.7】万元；，渠道终端销售部【3】项【17.4】万元；，市场经营部【5】项【13.9】万元；，数字生活与产品创新中心【8】项【22.3】万元；，10000号客户服务中心【2】项【3.4】万元；，财务部【1】项【0.5】万元；，客户服务管理部【3】项【8】万元；，网络和信息安全管理部【1】项【5.8】万元；，网络监控维护中心(NOC/SOC)【1】项【1.5】万元；
A15: 因现有的【BSS 3.0-受理中心】等系统由【中电福富信息科技有限公司】建设，本次采购为在原有系统上进行的软件开发，因此建议采用单一来源方式发起采购，与【中电福富信息科技有限公司】定向谈判。
A16: 总合计评审费用:【179】万元；大写:【壹佰柒拾玖万元整】,详见清单。
A17: 说明：以上预估费用均为不含税费用(税率6%)，工作量评审结果仅作为商务谈判的参考，最终以采购商务谈判结果为准！
A18: 需求责任人 及评审人员 (签字)
A21: 需求管理主管 (签字) | F21: 需求实施主管 (签字) | J21: 项目管理主管 (签字)
A23: 大数据和 AI中心主任 (签字) | F23: 云网运营事业部 总经理 (签字/盖章)
A25: xm | I25: ="-软件工作量评审清单表" -> -软件工作量评审清单表
A26: 评审单位： | E26: 项目经理： | F26: 张三189xxxxxxxx | H26: 评审小组 人员： | I26: 张三189xxxxxxxx、张三189xxxxxxxx、张三189xxxxxxxx
A27: 序 号 | B27: 一级 功能模块 | C27: 二级 功能模块 | D27: 三级 功能模块 | E27: 功能点 说明 | F27: 功能点 类别 | G27: 功能点 子类 | H27: 功能复杂度 等级 | I27: 上报工作量 (人日) | J27: 评审工作量 （人日） | K27: 预估不含税单价（人日/元） | L27: 预估费用 （万元） | M27: 审议结果 | N27: 对应技术方案 需求文档章节 | O27: 复杂度 系数说明
A28: 调整后总工作量（人日）= | I28: =ROUND(SUM(I$29:I$31)+I$36*I$32,0) -> #REF! | J28: =ROUND(SUM(J$29:J$31)+J$36*K$32,0) -> 70 | L28: =IFERROR(ROUND($J$28*$K$29/10000,2),"") -> 5.28
A29: 0 | B29: 需求流程管理评估 | C29: 需求沟通分析及确认 | E29: 包括前期需求方案沟通、需求评审等 | I29: 2 | J29: =I29 -> 2 | K29: =ROUND(800/1.06,3) -> 754.717 | L29: =IFERROR(ROUND($J29*$K29/10000,4),"") -> 0.1509
C30: 测试联调 | E30: 包括需求测试、业务测试、全流程穿测、接口联调等 | I30: =ROUNDDOWN($I$36*3%,0) -> 8 | J30: =I30 -> 8 | K30: =ROUND(800/1.06,3) -> 754.717 | L30: =IFERROR(ROUND($J30*$K30/10000,4),"") -> 0.6038
C31: 版本发布 | E31: 版本发布等 | I31: 0.5 | J31: =I31 -> 0.5 | K31: =ROUND(800/1.06,3) -> 754.717 | L31: =IFERROR(ROUND($J31*$K31/10000,4),"") -> 0.0377
B32: 调整因子 | C32: 响应速度 | D32: 1、客户信息查询响应时间要求是5秒之内 | F32: 5事务处理响应时间是毫秒级的 | H32: =#REF! -> #REF! | I32: =0.035*SUM($H$32:$H$35)+0.65 -> #REF! | J32: =VLOOKUP($F32,工作量标准!$C:$D,2,0) -> 5 | K32: =0.035*SUM($J$32:$J$35)+0.65 -> 1.21 | N32: 示例：P?页：6.1.1性能要求 | O32: =VLOOKUP($F32,工作量标准!$C:$E,3,0) -> 1、响应速度是指系统事务的处理速度，以响应时间(从事务开始到结束)计算。 2、如果系统有多项事务处理响应时间要求不同，按最高要求来计算，例如某些事务响应时间要求是秒级的，某些事务响应时间要求是毫秒级的，则计算毫秒级。
C33: 集成环境复杂性 | D33: 1、采用应用分布式式技术，HADOOP | F33: 4采用了数据库分布式技术 | H33: =#REF! -> #REF! | J33: =VLOOKUP($F33,工作量标准!$C:$D,2,0) -> 4 | N33: 示例：P?页：6.1.2技术要求 | O33: =VLOOKUP($F33,工作量标准!$C:$E,3,0) -> 1、集群(cluster)是指多台不同的服务器中部署相同的应用。 2、分布式(distributed)是指多台不同的服务器中部署多个不同的服务模块，不同服务模块通过连接有效协同。 3、PASS是指平台即服务(Platform as a Service,简称为PaaS)，是云计算三种服务模式之一,位于云计算服务架构的中间层,是云计算服务的重要组成部分，可提供基础计算能力、应用接口和开发环境、运行环境等。
C34: 可靠性 | D34: 1、要求全业务容灾 | F34: 3应用系统采用了双机热备(数据+应用)措施 | H34: =#REF! -> #REF! | J34: =VLOOKUP($F34,工作量标准!$C:$D,2,0) -> 3 | N34: 示例：P?页：6.1.3可靠性要求 | O34: =VLOOKUP($F34,工作量标准!$C:$E,3,0) -> 1、双机冷备是指通过特定的操作完成数据备份，主机出现故障后状态只能恢复到特定的备份时间点。 2、双机热备是指两台服务器同时运行,保持相同状态,在一台服务器出现问题时可由另一台直接提供服务。 3、异地容灾是指在不同地域(远距离)部署多套相同的应用或者数据库，当一地发生灾难后立刻由另一地的应用或数据库接管服务。
C35: 系统设计容量 | D35: 1、80TB数据容量 | F35: 4系统设计数据容量100TB至1000TB | H35: =#REF! -> #REF! | J35: =VLOOKUP($F35,工作量标准!$C:$D,2,0) -> 4 | N35: 示例：P?页：6.1.4系统容量要求 | O35: =VLOOKUP($F35,工作量标准!$C:$E,3,0) -> 0
A36: 未调整总工作量（人日）= | I36: =SUM(I$37:I$5024) -> 298 | J36: =SUM(J$37:J$5024) -> 49
A37: 1 | B37: 示例：01_分摊配置 | C37: 01_分摊配置能力提升 | D37: 01_公允价值配置管理 | E37: 示例：公允值新增 | F37: 界面类 | G37: 新增单个页面 | H37: A级 | I37: 5 | J37: =IFERROR(VLOOKUP($G37,工作量标准!$C:$D,2,0)*IF(IFERROR(FIND("A级",$H37),0)>0,1,IF(IFERROR(FIND("B级",$H37),0)>0,3,IF(IFERROR(FIND("C级",$H37),0)>0,5,IF(IFERROR(FIND("D级",$H37),0)>0,8,1)))),"") -> 2 | K37: =IF($J37="","",ROUND(800/1.06,3)) -> 754.717 | L37: =IFERROR(ROUND($J37*$K37/10000,4),"") -> 0.1509 | N37: 示例：P?页：4.1.1.1 公允值配置管理 | O37: =VLOOKUP($G37,工作量标准!$C:$E,3,0) -> 增加一个新的页面(或窗口界面)。页面(或窗口界面)功能是指向通过前台用户界面向用户提供的功能点，原则上包含页面(或窗口界面)的所有展现逻辑和相关处理逻辑，例如：清单查询页面功能包含了清单查询输入页面展现、获取清单数据、展现清单查询结果等。
A38: 2 | E38: 示例：公允值修改 | F38: 界面类 | G38: 修改已有页面 | H38: A级 | I38: 8 | J38: =IFERROR(VLOOKUP($G38,工作量标准!$C:$D,2,0)*IF(IFERROR(FIND("A级",$H38),0)>0,1,IF(IFERROR(FIND("B级",$H38),0)>0,3,IF(IFERROR(FIND("C级",$H38),0)>0,5,IF(IFERROR(FIND("D级",$H38),0)>0,8,1)))),"") -> 1 | K38: =IF($J38="","",ROUND(800/1.06,3)) -> 754.717 | L38: =IFERROR(ROUND($J38*$K38/10000,4),"") -> 0.0755 | N38: 示例：P?页：4.1.1.2 公允值配置管理 | O38: =VLOOKUP($G38,工作量标准!$C:$E,3,0) -> 修改已有的页面或窗口界面
A39: 3 | E39: 示例：公允值查询 | F39: 业务逻辑类 | G39: 新增业务逻辑 | H39: A级 | I39: 35 | J39: =IFERROR(VLOOKUP($G39,工作量标准!$C:$D,2,0)*IF(IFERROR(FIND("A级",$H39),0)>0,1,IF(IFERROR(FIND("B级",$H39),0)>0,3,IF(IFERROR(FIND("C级",$H39),0)>0,5,IF(IFERROR(FIND("D级",$H39),0)>0,8,1)))),"") -> 4 | K39: =IF($J39="","",ROUND(800/1.06,3)) -> 754.717 | L39: =IFERROR(ROUND($J39*$K39/10000,4),"") -> 0.3019 | N39: 示例：P?页：4.1.1.3 公允值配置管理 | O39: =VLOOKUP($G39,工作量标准!$C:$E,3,0) -> 增加新的业务逻辑。业务逻辑指没有用户界面的后台应用程序的业务逻辑(后台服务处理逻辑、后台定时任务处理逻辑等)，例如话单采集、批价处理等。在特殊情况下，可以是前台复杂业务逻辑，仅当前台处理逻辑相当复杂，难以包含在界面类等功能点工作量中时才考虑使用。不包含页面上的简单处理逻辑、报表指标的简单生成逻辑、流程环节的简单流转逻辑、接口的简单处理逻辑等，相关逻辑的工作量应包含在界面类、报表类、流程类、接口类的功能点中。
A40: 4 | D40: 02_销售品分摊规则配置管理 | E40: 示例：销售品分摊规则新增 | F40: 业务逻辑类 | G40: 调整业务逻辑 | H40: A级 | I40: 25 | J40: =IFERROR(VLOOKUP($G40,工作量标准!$C:$D,2,0)*IF(IFERROR(FIND("A级",$H40),0)>0,1,IF(IFERROR(FIND("B级",$H40),0)>0,3,IF(IFERROR(FIND("C级",$H40),0)>0,5,IF(IFERROR(FIND("D级",$H40),0)>0,8,1)))),"") -> 2 | K40: =IF($J40="","",ROUND(800/1.06,3)) -> 754.717 | L40: =IFERROR(ROUND($J40*$K40/10000,4),"") -> 0.1509 | N40: 示例：P?页：4.1.1.2 销售品分摊规则配置管理 | O40: =VLOOKUP($G40,工作量标准!$C:$E,3,0) -> 修改已有的业务逻辑。
A41: 5 | E41: 示例：销售品分摊规则修改 | F41: 接口类 | G41: 提供方新增接口 | H41: A级 | I41: 8 | J41: =IFERROR(VLOOKUP($G41,工作量标准!$C:$D,2,0)*IF(IFERROR(FIND("A级",$H41),0)>0,1,IF(IFERROR(FIND("B级",$H41),0)>0,3,IF(IFERROR(FIND("C级",$H41),0)>0,5,IF(IFERROR(FIND("D级",$H41),0)>0,8,1)))),"") -> 4 | K41: =IF($J41="","",ROUND(800/1.06,3)) -> 754.717 | L41: =IFERROR(ROUND($J41*$K41/10000,4),"") -> 0.3019 | N41: 示例：P?页：4.1.1.3 销售品分摊规则配置管理 | O41: =VLOOKUP($G41,工作量标准!$C:$E,3,0) -> 系统作为服务提供方向外部系统提供的接口。此工作量已包含所有横向系统(仅在集团层面或仅在省层面)的联调工作量，但不包含集团-省两级纵向接口联调的工作量，纵向接口联调的工作量通过纵向接口联调子类型反映。
A42: 6 | E42: 示例：销售品分摊规则删除 | F42: 接口类 | G42: 消费方新增接口 | H42: A级 | I42: 10 | J42: =IFERROR(VLOOKUP($G42,工作量标准!$C:$D,2,0)*IF(IFERROR(FIND("A级",$H42),0)>0,1,IF(IFERROR(FIND("B级",$H42),0)>0,3,IF(IFERROR(FIND("C级",$H42),0)>0,5,IF(IFERROR(FIND("D级",$H42),0)>0,8,1)))),"") -> 2 | K42: =IF($J42="","",ROUND(800/1.06,3)) -> 754.717 | L42: =IFERROR(ROUND($J42*$K42/10000,4),"") -> 0.1509 | N42: 示例：P?页：4.1.1.4 销售品分摊规则配置管理 | O42: =VLOOKUP($G42,工作量标准!$C:$E,3,0) -> 系统作为服务消费方调用外部系统提供的接口。此工作量包含所有横向系统的联调工作量，不包含两级纵向接口联调的工作量，纵向接口联调的工作量通过纵向接口联调子类型反映
A43: 7 | E43: 示例：销售品分摊规则查询 | F43: 接口类 | G43: 修改接口 | H43: A级 | I43: 12 | J43: =IFERROR(VLOOKUP($G43,工作量标准!$C:$D,2,0)*IF(IFERROR(FIND("A级",$H43),0)>0,1,IF(IFERROR(FIND("B级",$H43),0)>0,3,IF(IFERROR(FIND("C级",$H43),0)>0,5,IF(IFERROR(FIND("D级",$H43),0)>0,8,1)))),"") -> 2 | K43: =IF($J43="","",ROUND(800/1.06,3)) -> 754.717 | L43: =IFERROR(ROUND($J43*$K43/10000,4),"") -> 0.1509 | N43: 示例：P?页：4.1.1.5 销售品分摊规则配置管理 | O43: =VLOOKUP($G43,工作量标准!$C:$E,3,0) -> 修改提供方接口或消费方接口。此工作量已包含所有横向系统的联调工作量，但不包含两级纵向接口联调的工作量，纵向接口联调的工作量通过纵向接口联调子类型反映
A44: 8 | C44: 02_二级功能模块名称 | D44: 01_三级功能模块名称 | E44: 01_功能点 | F44: 接口类 | G44: 纵向接口联调 | H44: A级 | I44: 8 | J44: =IFERROR(VLOOKUP($G44,工作量标准!$C:$D,2,0)*IF(IFERROR(FIND("A级",$H44),0)>0,1,IF(IFERROR(FIND("B级",$H44),0)>0,3,IF(IFERROR(FIND("C级",$H44),0)>0,5,IF(IFERROR(FIND("D级",$H44),0)>0,8,1)))),"") -> 0.5 | K44: =IF($J44="","",ROUND(800/1.06,3)) -> 754.717 | L44: =IFERROR(ROUND($J44*$K44/10000,4),"") -> 0.0377 | N44: 示例：P?页：5.1.1.生产环境压力测试 | O44: =VLOOKUP($G44,工作量标准!$C:$E,3,0) -> 系统与其他系统的交互接口的联调。纵向接口联调的基准工作量和联调系统数相关，等于0.5*联调系统数
A45: 9 | E45: 2_功能点 | F45: 流程类 | G45: 配置流程新增流程 | H45: A级 | I45: 30 | J45: =IFERROR(VLOOKUP($G45,工作量标准!$C:$D,2,0)*IF(IFERROR(FIND("A级",$H45),0)>0,1,IF(IFERROR(FIND("B级",$H45),0)>0,3,IF(IFERROR(FIND("C级",$H45),0)>0,5,IF(IFERROR(FIND("D级",$H45),0)>0,8,1)))),"") -> 4 | K45: =IF($J45="","",ROUND(800/1.06,3)) -> 754.717 | L45: =IFERROR(ROUND($J45*$K45/10000,4),"") -> 0.3019 | N45: 示例：P?页：6.1.1.5 纵向接口联调 | O45: =VLOOKUP($G45,工作量标准!$C:$E,3,0) -> 配置新的业务或管理流程，包括流程环节定义、流程编排等
...

Sheet 工作量标准
A1: 功能点子类编码 | B1: 功能点类别 | C1: 功能点子类 | D1: 基准工作量(人日) | E1: 功能点类别说明 | F1: 复杂度系数说明 | G1: 复杂度 | H1: 调整系数
A2: 0101 | B2: 界面类 | C2: 新增单个页面 | D2: 2 | E2: 增加一个新的页面(或窗口界面)。页面(或窗口界面)功能是指向通过前台用户界面向用户提供的功能点，原则上包含页面(或窗口界面)的所有展现逻辑和相关处理逻辑，例如：清单查询页面功能包含了清单查询输入页面展现、获取清单数据、展现清单查询结果等。 | F2: A级:界面展示信息(动态元素)0-10个。动态元素指从后台服务获取的数据项或者动画元素。 B级:界面展示信息(动态元素)11-20个 C级:界面展示信息(动态元素)21-30个 D级:界面展示信息(动态元素)大于30个 | G2: A级 | H2: 1
A3: 0102 | B3: 界面类 | C3: 修改已有页面 | D3: 1 | E3: 修改已有的页面或窗口界面 | F3: A级:页面细节调整，调整点1-10个 B级:页面细节调整，调整点11-20个 C级:页面细节调整，调整点21-30个 D级:页面细节调整，调整点大于30个 | G3: B级 | H3: 3
A4: 0201 | B4: 业务逻辑类 | C4: 新增业务逻辑 | D4: 4 | E4: 增加新的业务逻辑。业务逻辑指没有用户界面的后台应用程序的业务逻辑(后台服务处理逻辑、后台定时任务处理逻辑等)，例如话单采集、批价处理等。在特殊情况下，可以是前台复杂业务逻辑，仅当前台处理逻辑相当复杂，难以包含在界面类等功能点工作量中时才考虑使用。不包含页面上的简单处理逻辑、报表指标的简单生成逻辑、流程环节的简单流转逻辑、接口的简单处理逻辑等，相关逻辑的工作量应包含在界面类、报表类、流程类、接口类的功能点中。 | F4: A级:业务逻辑简单：例如：在CRM后台逻辑中增加涉及到1-8个实体对象(表)的操作(包含查、增、删、改)，如用户基本信息查询在计费后台逻辑中增加1-3个参数或因子、增加监控、处理进程调整等在MSS后台逻辑中增加赠送物资入项目库调用项目预算的逻辑在OSS后台逻辑中增加业务判断点少于3个。 B级:复杂度一般：例如：在CRM后台逻辑中增加8个以上实体对象操作，业务逻辑中包含外部接口调用，且对接口调用进行判断校验和解析处理，如客户信息录入(包含身份证读卡识别)在计费后台逻辑中增加参数同时进行参数校验，处理日志优化，消息报文新增值并解析入库等在MSS后台逻辑中增加总部根据推荐采购方式不同带出不同采购建议单的业务逻辑在OSS后台逻辑中增加业务判断点在3-10个。 C级:复杂度中等：例如：在CRM后台逻辑中增加批量数据操作，且批量操作数据需要后续监控处理的，如套餐到期提醒，并记录提醒成功、失败标志等在计费后台逻辑中增加计费事件、账务事件，数据模型调整增加字段，新增文件交互等在MSS后台逻辑中增加跨省调拨不同法人业务逻辑处理在OSS后台逻辑中增加业务判断点在10-15个。 D级:复杂度高等：例如：在CRM后台逻辑中增加当前系统模型无法支持该业务逻辑，需要涉及模型改造(包含对原有模型的改造和新增)才能支持在计费后台逻辑中增加出账规则、计费规则、结算规则调整，内存模型、内存计算方式、内存架构调整，新增消息交互流程等在MSS后台逻辑中增加个人工作台长期挂账多级视图。 | G4: C级 | H4: 5
A5: 0202 | B5: 业务逻辑类 | C5: 调整业务逻辑 | D5: 2 | E5: 修改已有的业务逻辑。 | F5: A级:业务逻辑简单：例如：在CRM后台逻辑中修改涉及到1-8个实体对象(表)的操作(包含查、增、删、改)，如用户基本信息查询在计费后台逻辑中修改1-3个参数或因子、增加监控、处理进程调整等在MSS后台逻辑中修改赠送物资入项目库调用项目预算的逻辑在OSS后台逻辑中修改业务判断点少于3个。 B级:复杂度一般例如：在CRM后台逻辑中修改8个以上实体对象操作，业务逻辑中包含外部接口调用，且对接口调用进行判断校验和解析处理，如客户信息录入(包含身份证读卡识别)在计费后台逻辑中修改参数同时进行参数校验，处理日志优化，消息报文新增值并解析入库等在MSS后台逻辑中修改总部根据推荐采购方式不同带出不同采购建议单的业务逻辑在OSS后台逻辑中增加业务判断点在15个以上在OSS后台逻辑中修改业务判断点在3-10个。 C级:复杂度中等：例如：在CRM后台逻辑中修改批量数据操作，且批量操作数据需要后续监控处理的，如套餐到期提醒，并记录提醒成功、失败标志等在计费后台逻辑中修改计费事件、账务事件，数据模型调整增加字段，新增文件交互等在MSS后台逻辑中修改跨省调拨不同法人业务逻辑处理在OSS后台逻辑中修改业务判断点在10-15个。 D级:复杂度高等：例如：在CRM后台逻辑中修改当前系统模型无法支持该业务逻辑在计费后台逻辑中修改出账规则、计费规则、结算规则调整，内存模型、内存计算方式、内存架构调整，新增消息交互流程等。在MSS后台逻辑中修改个人工作台长期挂账多级视图在OSS后台逻辑中修改业务判断点在15个以上。 | G5: D级 | H5: 8
A6: 0301 | B6: 接口类 | C6: 提供方新增接口 | D6: 4 | E6: 系统作为服务提供方向外部系统提供的接口。此工作量已包含所有横向系统(仅在集团层面或仅在省层面)的联调工作量，但不包含集团-省两级纵向接口联调的工作量，纵向接口联调的工作量通过纵向接口联调子类型反映。 | F6: A级:涉及业务字段1-10个 B级:涉及业务字段11-30个 C级:涉及业务字段31-60个 D级:涉及业务字段大于60个
A7: 0302 | B7: 接口类 | C7: 消费方新增接口 | D7: 2 | E7: 系统作为服务消费方调用外部系统提供的接口。此工作量包含所有横向系统的联调工作量，不包含两级纵向接口联调的工作量，纵向接口联调的工作量通过纵向接口联调子类型反映 | F7: A级:涉及业务字段1-10个 B级:涉及业务字段11-30个 C级:涉及业务字段31-60个 D级:涉及业务字段大于60
A8: 0303 | B8: 接口类 | C8: 修改接口 | D8: 2 | E8: 修改提供方接口或消费方接口。此工作量已包含所有横向系统的联调工作量，但不包含两级纵向接口联调的工作量，纵向接口联调的工作量通过纵向接口联调子类型反映 | F8: A级:涉及业务字段1-10个 B级:涉及业务字段11-30个 C级:涉及业务字段31-60个 D级:涉及业务字段大于60个
A9: 0304 | B9: 接口类 | C9: 纵向接口联调 | D9: 0.5 | E9: 系统与其他系统的交互接口的联调。纵向接口联调的基准工作量和联调系统数相关，等于0.5*联调系统数 | F9: A级:准实时分钟级接口交互(如文件)，且涉及业务字段1-15个 B级:准实时分钟级接口交互(如文件)，且涉及业务字段大于15个 C级:实时秒级接口交互(如消息)，且涉及业务字段1-10个 D级:实时秒级接口交互(如消息)，且涉及业务字段大于10个
A10: 0401 | B10: 流程类 | C10: 配置流程新增流程 | D10: 4 | E10: 配置新的业务或管理流程，包括流程环节定义、流程编排等 | F10: A级:配置环节和控制线1-10个。 B级:配置环节和控制线11-20个 C级:配置环节和控制线21-30个 D级:配置环节和控制线大于30个
A11: 0402 | B11: 流程类 | C11: 配置流程修改流程 | D11: 2 | E11: 修改业务或管理流程的配置，包括流程环节定义、流程编排等 | F11: A级:配置环节和控制线1-5个 B级:配置环节和控制线6-10个 C级:配置环节和控制线11-20个 D级:配置环节和控制线大于20个
A12: 0501 | B12: 报表类 | C12: 新增报表 | D12: 2 | E12: 以程序开发的方式增加新报表 | F12: A级:报表元素1-5个 B级:报表元素在6-10个 C级:报表元素在11-20个 D级:报表元素大于20个
A13: 0502 | B13: 报表类 | C13: 变更报表 | D13: 0.5 | E13: 以程序开发的方式修改原报表 | F13: A级:报表元素1-5个 B级:报表元素在6-10个 C级:报表元素在11-20个 D级:报表元素大于20个
A14: 0503 | B14: 报表类 | C14: 配置报表 | D14: 0.5 | E14: 使用报表配置工具配置新报表 | F14: A级:报表字段1-15个 B级:报表字段16-30个 C级:报表字段31-50个 D级:报表字段50个以上
A15: 0601 | B15: 数据处理类 | C15: 新增导出模板 | D15: 1 | E15: 新增导出数据的模板，如导出EXCEL文件数据、PDF文件数据或文本文件数据等 | F15: A级:导出信息1-10个 B级:导出信息11个-20个 C级:导出信息21个-30个 D级:导出信息大于30个
A16: 0602 | B16: 数据处理类 | C16: 已有导出模板修改 | D16: 1 | E16: 修改已有导出数据的模板 | F16: A级:修改点1-10个 B级:修改点11-20个 C级:修改点21-30个 D级:修改点大于30个
A17: 0603 | B17: 数据处理类 | C17: 新增导入功能 | D17: 1 | E17: 新增批量导入数据的功能 | F17: A级:基于单张表导入数据，简单逻辑 B级:基于单张表导入数据，复杂逻辑 C级:基于多张表导入数据，简单逻辑 D级:基于多张表导入数据，复杂逻辑
... A37: 0809 | B37: 推广类 | C37: 网络验证 | D37: 1 | E37: 指推广中需要的网络配置与验证工作。按网络规划方案进行技术验证，保证网络畅通和效率。 | F37: A级:网络策略逻辑简单，所需配置网络节点1-2个 B级:复杂度一般，所需配置网络节点数3-5个 C级:复杂度中等，所需配置网络节点数6-10个 D级:复杂度高等，所需配置网络节点数大于10个
B39: 调整因子 | C39: 影响度界定标准 | D39: 分值 | E39: 备注
B40: 响应速度 | C40: 0按业务最高响应速度要求，事务处理耗时无严格要求 | D40: 0 | E40: 1、响应速度是指系统事务的处理速度，以响应时间(从事务开始到结束)计算。 2、如果系统有多项事务处理响应时间要求不同，按最高要求来计算，例如某些事务响应时间要求是秒级的，某些事务响应时间要求是毫秒级的，则计算毫秒级。
C41: 1事务处理响应时间在2小时以上 | D41: 1 | E41: 1、响应速度是指系统事务的处理速度，以响应时间(从事务开始到结束)计算。 2、如果系统有多项事务处理响应时间要求不同，按最高要求来计算，例如某些事务响应时间要求是秒级的，某些事务响应时间要求是毫秒级的，则计算毫秒级。
C42: 2事务处理响应时间在1-2小时之间 | D42: 2 | E42: 1、响应速度是指系统事务的处理速度，以响应时间(从事务开始到结束)计算。 2、如果系统有多项事务处理响应时间要求不同，按最高要求来计算，例如某些事务响应时间要求是秒级的，某些事务响应时间要求是毫秒级的，则计算毫秒级。
C43: 3事务处理响应时间是分钟级的 | D43: 3 | E43: 1、响应速度是指系统事务的处理速度，以响应时间(从事务开始到结束)计算。 2、如果系统有多项事务处理响应时间要求不同，按最高要求来计算，例如某些事务响应时间要求是秒级的，某些事务响应时间要求是毫秒级的，则计算毫秒级。
C44: 4事务处理响应时间是秒级的 | D44: 4 | E44: 1、响应速度是指系统事务的处理速度，以响应时间(从事务开始到结束)计算。 2、如果系统有多项事务处理响应时间要求不同，按最高要求来计算，例如某些事务响应时间要求是秒级的，某些事务响应时间要求是毫秒级的，则计算毫秒级。
C45: 5事务处理响应时间是毫秒级的 | D45: 5 | E45: 1、响应速度是指系统事务的处理速度，以响应时间(从事务开始到结束)计算。 2、如果系统有多项事务处理响应时间要求不同，按最高要求来计算，例如某些事务响应时间要求是秒级的，某些事务响应时间要求是毫秒级的，则计算毫秒级。
B46: 集成环境复杂性 | C46: 0采用单机模式 | D46: 0 | E46: 1、集群(cluster)是指多台不同的服务器中部署相同的应用。 2、分布式(distributed)是指多台不同的服务器中部署多个不同的服务模块，不同服务模块通过连接有效协同。 3、PASS是指平台即服务(Platform as a Service,简称为PaaS)，是云计算三种服务模式之一,位于云计算服务架构的中间层,是云计算服务的重要组成部分，可提供基础计算能力、应用接口和开发环境、运行环境等。
C47: 1采用数据库与应用服务分离模式 | D47: 1 | E47: 1、集群(cluster)是指多台不同的服务器中部署相同的应用。 2、分布式(distributed)是指多台不同的服务器中部署多个不同的服务模块，不同服务模块通过连接有效协同。 3、PASS是指平台即服务(Platform as a Service,简称为PaaS)，是云计算三种服务模式之一,位于云计算服务架构的中间层,是云计算服务的重要组成部分，可提供基础计算能力、应用接口和开发环境、运行环境等。
C48: 2采用了传统集群技术(无采用分布式技术) | D48: 2 | E48: 1、集群(cluster)是指多台不同的服务器中部署相同的应用。 2、分布式(distributed)是指多台不同的服务器中部署多个不同的服务模块，不同服务模块通过连接有效协同。 3、PASS是指平台即服务(Platform as a Service,简称为PaaS)，是云计算三种服务模式之一,位于云计算服务架构的中间层,是云计算服务的重要组成部分，可提供基础计算能力、应用接口和开发环境、运行环境等。
C49: 3采用了应用分布式技术 | D49: 3 | E49: 1、集群(cluster)是指多台不同的服务器中部署相同的应用。 2、分布式(distributed)是指多台不同的服务器中部署多个不同的服务模块，不同服务模块通过连接有效协同。 3、PASS是指平台即服务(Platform as a Service,简称为PaaS)，是云计算三种服务模式之一,位于云计算服务架构的中间层,是云计算服务的重要组成部分，可提供基础计算能力、应用接口和开发环境、运行环境等。
C50: 4采用了数据库分布式技术 | D50: 4 | E50: 1、集群(cluster)是指多台不同的服务器中部署相同的应用。 2、分布式(distributed)是指多台不同的服务器中部署多个不同的服务模块，不同服务模块通过连接有效协同。 3、PASS是指平台即服务(Platform as a Service,简称为PaaS)，是云计算三种服务模式之一,位于云计算服务架构的中间层,是云计算服务的重要组成部分，可提供基础计算能力、应用接口和开发环境、运行环境等。
C51: 5采用了PAAS云技术 | D51: 5 | E51: 1、集群(cluster)是指多台不同的服务器中部署相同的应用。 2、分布式(distributed)是指多台不同的服务器中部署多个不同的服务模块，不同服务模块通过连接有效协同。 3、PASS是指平台即服务(Platform as a Service,简称为PaaS)，是云计算三种服务模式之一,位于云计算服务架构的中间层,是云计算服务的重要组成部分，可提供基础计算能力、应用接口和开发环境、运行环境等。
B52: 可靠性 | C52: 0应用系统无可靠性要求 | D52: 0 | E52: 1、双机冷备是指通过特定的操作完成数据备份，主机出现故障后状态只能恢复到特定的备份时间点。 2、双机热备是指两台服务器同时运行,保持相同状态,在一台服务器出现问题时可由另一台直接提供服务。 3、异地容灾是指在不同地域(远距离)部署多套相同的应用或者数据库，当一地发生灾难后立刻由另一地的应用或数据库接管服务。
C53: 1应用系统采用了双机冷备措施 | D53: 1 | E53: 1、双机冷备是指通过特定的操作完成数据备份，主机出现故障后状态只能恢复到特定的备份时间点。 2、双机热备是指两台服务器同时运行,保持相同状态,在一台服务器出现问题时可由另一台直接提供服务。 3、异地容灾是指在不同地域(远距离)部署多套相同的应用或者数据库，当一地发生灾难后立刻由另一地的应用或数据库接管服务。
C54: 2应用系统采用了双机热备(数据)措施 | D54: 2 | E54: 1、双机冷备是指通过特定的操作完成数据备份，主机出现故障后状态只能恢复到特定的备份时间点。 2、双机热备是指两台服务器同时运行,保持相同状态,在一台服务器出现问题时可由另一台直接提供服务。 3、异地容灾是指在不同地域(远距离)部署多套相同的应用或者数据库，当一地发生灾难后立刻由另一地的应用或数据库接管服务。
C55: 3应用系统采用了双机热备(数据+应用)措施 | D55: 3 | E55: 1、双机冷备是指通过特定的操作完成数据备份，主机出现故障后状态只能恢复到特定的备份时间点。 2、双机热备是指两台服务器同时运行,保持相同状态,在一台服务器出现问题时可由另一台直接提供服务。 3、异地容灾是指在不同地域(远距离)部署多套相同的应用或者数据库，当一地发生灾难后立刻由另一地的应用或数据库接管服务。
C56: 4应用系统采用了数据异地容灾措施 | D56: 4 | E56: 1、双机冷备是指通过特定的操作完成数据备份，主机出现故障后状态只能恢复到特定的备份时间点。 2、双机热备是指两台服务器同时运行,保持相同状态,在一台服务器出现问题时可由另一台直接提供服务。 3、异地容灾是指在不同地域(远距离)部署多套相同的应用或者数据库，当一地发生灾难后立刻由另一地的应用或数据库接管服务。
C57: 5应用系统采用了业务异地容灾措施 | D57: 5 | E57: 1、双机冷备是指通过特定的操作完成数据备份，主机出现故障后状态只能恢复到特定的备份时间点。 2、双机热备是指两台服务器同时运行,保持相同状态,在一台服务器出现问题时可由另一台直接提供服务。 3、异地容灾是指在不同地域(远距离)部署多套相同的应用或者数据库，当一地发生灾难后立刻由另一地的应用或数据库接管服务。
B58: 系统设计容量 | C58: 0系统设计数据容量10GB以下 | D58: 0 | E58: 系统设计数据容量是指预期系统可支持的最大数据存储容量
C59: 1系统设计数据容量10GB至100GB | D59: 1
C60: 2系统设计数据容量100GB至1TB | D60: 2
...

Sheet 功能点类型
A1: 界面类 | B1: 业务逻辑类 | C1: 接口类 | D1: 流程类 | E1: 报表类 | F1: 数据处理类 | G1: 实施类 | H1: 推广类(仅全国集中系统选)
A2: 新增单个页面 | B2: 新增业务逻辑 | C2: 提供方新增接口 | D2: 配置流程新增流程 | E2: 新增报表 | F2: 新增导出模板 | G2: 主机配置 | H2: 业务差异分析
A3: 修改已有页面 | B3: 调整业务逻辑 | C3: 消费方新增接口 | D3: 配置流程修改流程 | E3: 变更报表 | F3: 已有导出模板修改 | G3: 存储扩容配置 | H3: 参数配置
C4: 修改接口 | E4: 配置报表 | F4: 新增导入功能 | G4: 网络策略配置 | H4: 业务端到端测试
C5: 纵向接口联调 | F5: 已有导入功能修改 | G5: 应用部署 | H5: 软件升级及安装
F6: 临时取数 | H6: 生产环境压力测试
F7: 数据批量修改 | H7: 数据脱敏
F8: 数据配置 | H8: 数据收集与清理
F9: 数据稽核 | H9: 数据割接
F10: 数据加工 | H10: 网络验证
F11: 数据测算
A13: T1.界面类st1.新增单个页面 | B13: T1.界面类st2.修改已有页面 | C13: T2.业务逻辑类st1.新增业务逻辑 | D13: T2.业务逻辑类st2.调整业务逻辑 | E13: T3.接口类st1.提供方新增接口 | F13: T3.接口类st2.消费方新增接口 | G13: T3.接口类st3.修改接口 | H13: T3.接口类st4.纵向接口联调 | I13: T4.流程类st1.配置流程新增流程 | J13: T4.流程类st2.配置流程修改流程 | K13: T5.报表类st1.新增报表 | L13: T5.报表类st2.变更报表 | M13: T5.报表类st3.配置报表 | N13: T6.数据处理类st1.新增导出模板 | O13: T6.数据处理类st2.已有导出模板修改 | P13: T6.数据处理类st3.新增导入功能 | Q13: T6.数据处理类st4.已有导入功能修改 | R13: T6.数据处理类st5.临时取数 | S13: T6.数据处理类st6.数据批量修改 | T13: T6.数据处理类st7.数据配置 | U13: T6.数据处理类st8.数据稽核 | V13: T6.数据处理类st9.数据加工 | W13: T6.数据处理类st10.数据测算 | X13: T7.实施类st1.主机配置 | Y13: T7.实施类st2.存储扩容配置 | Z13: T7.实施类st3.网络策略配置 | AA13: T7.实施类st4应用部署 | AB13: T8.推广类st1.业务差异分析 | AC13: T8.推广类st2.参数配置 | AD13: T8.推广类st3.业务端到端测试 | AE13: T8.推广类st4.软件升级及安装 | AF13: T8.推广类st5.生产环境压力测试 | AG13: T8.推广类st6.数据脱敏 | AH13: T8.推广类st7.数据收集与清理 | AI13: T8.推广类st8.数据割接 | AJ13: T8.推广类st.9 网络验证
A14: 增加一个新的页面(或窗口界面) | B14: 修改已有的页面或窗口界面 | C14: 增加新的业务逻辑 | D14: 修改已有的业务逻辑 | E14: 系统作为服务提供方向外部系统提供的接口 | F14: 系统作为服务消费方调用外部系统提供的接口 | G14: 修改提供方接口或消费方接口 | H14: 系统与省份/专业子公司系统的交互接口联调 | I14: 配置新的业务或管理流程，包括流程环节定义、流程编排等 | J14: 修改业务或管理流程的配置，包括流程环节定义、流程编排等 | K14: 以程序开发的方式增加新报表 | L14: 以程序开发的方式修改原报表 | M14: 使用报表配置工具配置新报表 | N14: 新增导出数据的模板，如导出EXCEL文件数据、PDF文件数据或文本文件数据等 | O14: 修改已有导出数据的模板 | P14: 新增批量导入数据的功能 | Q14: 修改已有批量导入数据的功能，如导入EXCEL文件数据、文本文件数据等 | R14: 根据业务部门临时性的、针对特定需求提供数据 | S14: 对数据进行批量修改 | T14: 配置系统需要的数据，包括业务数据配置、系统数据配置等，如业务规则配置、系统参数配置等 | U14: 根据稽核规则进行数据采集、比对、差异分析等 | V14: 根据业务需求对数据进行加工处理，如补充数据、拆分数据、合并数据等等 | W14: 根据业务需求进行数据预处理、模型假设、模型设计与实现、模型评估等 | X14: 指因cpu扩容、内存扩容导致的主机配置实施工作 | Y14: 指因存储空间扩容导致的配置工作实施工作 | Z14: 指网络参数配置实施工作 | AA14: 指平台、应用部署实施工作 | AB14: 指对省业务与集团业务进行差异分析的工作,仅适合于全国大集中系统 | AC14: 指在推广系统上进行系统或业务参数配置的工作,仅适合于全国大集中系统 | AD14: 是指业务的端到端测试工作,仅适合于全国大集中系统 | AE14: 应用软件服务器和终端安装或版本升级,,仅适合于全国大集中系统 | AF14: 指在生产环境中进行的性能测试工作,仅适合于全国大集中系统 | AG14: 指对数据进行脱敏处理的工作,仅适合于全国大集中系统 | AH14: 指推广中需要的基础数据收集和数据清理工作,仅适合于全国大集中系统 | AI14: 指数据由旧系统迁移到新系统的处理工作,仅适合于全国大集中系统 | AJ14: 指推广中需要的网络配置与验证工作,仅适合于全国大集中系统
A15: A级:界面展示信息0-10个 | B15: A级:页面细节调整点1-10个 | C15: A级:业务逻辑简单:A增加涉及到1-8个实体对象,B增加1-3个参数,C增加业务判断点小于3个 | D15: A级:业务逻辑简单:A修改到1-8个实体对象,B修改1-3个参数,C修改业务判断点少于3个 | E15: A级:涉及业务字段1-10个 | F15: A级:涉及业务字段1-10个 | G15: A级:涉及业务字段1-10个 | H15: A级:准实时分钟级接口交互(如文件)，且涉及业务字段1-15个 | I15: A级:配置环节和控制线1-10个 | J15: A级:配置环节和控制线1-5个 | K15: A级:报表元素1-5个 | L15: A级:报表元素1-5个 | M15: A级:报表字段1-15个 | N15: A级:导出信息1-10个 | O15: A级:修改点1-10个 | P15: A级:基于单张表导入数据简单逻辑 | Q15: A级:基于单张表修改导入功能简单逻辑 | R15: A级:基于单张表直接取数简单逻辑 | S15: A级:基于单张表修改数据，简单逻辑 | T15: A级:基于单张表配置数据简单逻辑 | U15: A级:基于单张表取数稽核简单逻辑 | V15: A级:基于单张表进行数据加工，简单逻辑 | W15: A级:基于单张表取数测算简单逻辑 | X15: A级:涉及1-10台主机(含虚拟机) | Y15: A级:1-10台应用主机存储扩容配置 | Z15: A级:网络策略逻辑简单,所需配置网络节点数1-2个 | AA15: A级:平台应用部署简单,对相应服务简单部署启动即可 | AB15: A级:单系统简单的方案和流程 | AC15: A级:基于单张表配置数据简单逻辑 | AD15: A级:基于单系统简单流程 | AE15: A级:平台应用部署简单，对相应服务简单部署启动即可 | AF15: A级:性能测试案例1-5个 | AG15: A级:数据脱敏1-5个字段 | AH15: A级:收集与清理1-10个字段 | AI15: A级:割接的数据1-25个字段 | AJ15: A级:网络策略逻辑简单，所需配置网络节点1-2个
A16: B级:界面展示信息11-20个 | B16: B级:页面细节调整点11-20个 | C16: B级:复杂度一般:A增加8个以上实体对象操作，B增加参数同时进行参数校验,C增加业务判断点3-10个 | D16: B级:复杂度一般:A修改8个以上实体对象,B修改参数同时校验等,C增加业务判断点15个以上,修改业务判断点3-10个 | E16: B级:涉及业务字段11-30个 | F16: B级:涉及业务字段11-30个 | G16: B级:涉及业务字段11-30个 | H16: B级:准实时分钟级接口交互(如文件)，且涉及业务字段大于15个 | I16: B级:配置环节和控制线11-20个 | J16: B级:配置环节和控制线6-10个 | K16: B级:报表元素在6-10个 | L16: B级:报表元素在6-10个 | M16: B级:报表字段16-30个 | N16: B级:导出信息11个-20个 | O16: B级:修改点11-20个 | P16: B级:基于单张表导入数据复杂逻辑 | Q16: B级:基于单张表修改导入功能复杂逻辑 | R16: B级:基于单张表直接取数复杂逻辑 | S16: B级:基于单张表修改数据，复杂逻辑 | T16: B级:基于单张表配置数据复杂逻辑 | U16: B级:基于单张表取数稽核复杂逻辑 | V16: B级:基于单张表进行数据加工，复杂逻辑 | W16: B级:基于单张表取数测算复杂逻辑 | X16: B级:涉及11-20台主机(含虚拟机) | Y16: B级:10台以上应用主机存储扩容配置 | Z16: B级:复杂度一般,所需配置网络节点数3-5个 | AA16: B级:平台应用部署后,单服务参数配置复杂,参数调整在1-5个之间 | AB16: B级:单系统复杂的方案和流程 | AC16: B级:基于单张表配置数据复杂逻辑 | AD16: B级:基于单系统复杂流程 | AE16: B级:平台应用部署后，单服务参数配置复杂，参数调整在1-5个之间 | AF16: B级:性能测试案例6-10个 | AG16: B级:数据脱敏6-10个字段 | AH16: B级:收集与清理11-20个字段 | AI16: B级:割接的数据26-50个字段 | AJ16: B级:复杂度一般，所需配置网络节点数3-5个
A17: C级:界面展示信息21-30个 | B17: C级:页面细节调整点21-30个 | C17: C级:复杂度中等:A增加批量数据操作,且批量操作数据需要后续监控处理的,B增加模型调整等,C增加业务判断点在10-15个 | D17: C级:复杂度中等:A修改批量数据操作且需后续监控处理,B修改调整增加字段等,C修改业务判断点10-15个 | E17: C级:涉及业务字段31-60个 | F17: C级:涉及业务字段31-60个 | G17: C级:涉及业务字段31-60个 | H17: C级:实时秒级接口交互(如消息)，且涉及业务字段1-10个 | I17: C级:配置环节和控制线21-30个 | J17: C级:配置环节和控制线11-20个 | K17: C级:报表元素在11-20个 | L17: C级:报表元素在11-20个 | M17: C级:报表字段31-50个 | N17: C级:导出信息21个-30个 | O17: C级:修改点21-30个 | P17: C级:基于多张表导入数据简单逻辑 | Q17: C级:基于多张表修改导入功能简单逻辑 | R17: C级:基于多张表直接取数简单逻辑 | S17: C级:基于多张表修改数据，简单逻辑 | T17: C级:基于多张表配置数据简单逻辑 | U17: C级:基于多张表取数稽核简单逻辑 | V17: C级:基于多张表进行数据加工，简单逻辑 | W17: C级:基于多张表取数测算简单逻辑 | X17: C级:涉及21-100台主机(含虚拟机) | Y17: C级:1-5套物理数据库存储扩容配置 | Z17: C级:复杂度中等,所需配置网络节点数6-10个 | AA17: C级:平台应用存在两种依赖关系或单点登录关系,参数调整在5个以上 | AB17: C级:多系统跨流程的简单方案和流程 | AC17: C级:基于多张表配置数据简单逻辑 | AD17: C级:基于多系统简单流程 | AE17: C级:平台应用存在两种依赖关系或单点登录关系，并且参数调整在5个以上 | AF17: C级:性能测试案例11-20个 | AG17: C级:数据脱敏11-15个字段 | AH17: C级:收集与清理21-30个字段 | AI17: C级:割接的数据51-75个字段 | AJ17: C级:复杂度中等，所需配置网络节点数6-10个
A18: D级:界面展示信息大于30个 | B18: D级:页面细节调整点大于30个 | C18: D级:复杂度高等:A需要模型改造才能支持,B增加规则调整等,C增加多级视图等 | D18: D级:复杂度高等:A修改当前系统模型无法支持,B修改调整新增消息交互流程等,C修改业务判断点15个以上 | E18: D级:涉及业务字段大于60个 | F18: D级:涉及业务字段大于60个 | G18: D级:涉及业务字段大于60个 | H18: D级:实时秒级接口交互(如消息)，且涉及业务字段大于10个 | I18: D级:配置环节和控制线大于30 | J18: D级:配置环节和控制线大于20个 | K18: D级:报表元素大于20个 | L18: D级:报表元素大于20个 | M18: D级:报表字段50个以上 | N18: D级:导出信息大于30个 | O18: D级:修改点大于30个 | P18: D级:基于多张表导入数据复杂逻辑 | Q18: D级:基于多张表修改导入功能复杂逻辑 | R18: D级:基于多表直接取数复杂逻辑 | S18: D级:基于多张表修改数据，复杂逻辑 | T18: D级:基于多张表配置数据复杂逻辑 | U18: D级:基于多张表取数稽核复杂逻辑 | V18: D级:基于多张表进行数据加工，复杂逻辑 | W18: D级:基于多张表取数测算复杂逻辑 | X18: D级:大于100台主机(含虚拟机) | Y18: D级:5套以上物理数据库存储扩容配置 | Z18: D级:复杂度高等,所需配置网络节点数大于10个 | AA18: D级:部署复杂,需要依赖两个及以上组件,配置参数在10个以上 | AB18: D级:多系统跨流程的复杂方案和流程 | AC18: D级:基于多张表配置数据复杂逻辑 | AD18: D级:基于多系统复杂流程 | AE18: D级:部署复杂，需要依赖两个及以上组件，并且配置参数在10个以上 | AF18: D级:性能测试案例大于20个 | AG18: D级:数据脱敏大于15个字段 | AH18: D级:收集与清理大于30个字段 | AI18: D级:割接的数据大于75个字段 | AJ18: D级:复杂度高等，所需配置网络节点数大于10个
A19: 增加一个新的页面(或窗口界面) A级:界面展示信息0-10个 B级:界面展示信息11-20个 C级:界面展示信息21-30个 D级:界面展示信息大于30个 | B19: 修改已有的页面或窗口界面 A级:页面细节调整点1-10个 B级:页面细节调整点11-20个 C级:页面细节调整点21-30个 D级:页面细节调整点大于30个 | C19: 增加新的业务逻辑 A级:业务逻辑简单:A增加涉及到1-8个实体对象,B增加1-3个参数,C增加业务判断点小于3个 B级:复杂度一般:A增加8个以上实体对象操作，B增加参数同时进行参数校验,C增加业务判断点3-10个 C级:复杂度中等:A增加批量数据操作,且批量操作数据需要后续监控处理的,B增加模型调整等,C增加业务判断点在10-15个 D级:复杂度高等:A需要模型改造才能支持,B增加规则调整等,C增加多级视图等 | D19: 修改已有的业务逻辑 A级:业务逻辑简单:A修改到1-8个实体对象,B修改1-3个参数,C修改业务判断点少于3个 B级:复杂度一般:A修改8个以上实体对象,B修改参数同时校验等,C增加业务判断点15个以上,修改业务判断点3-10个 C级:复杂度中等:A修改批量数据操作且需后续监控处理,B修改调整增加字段等,C修改业务判断点10-15个 D级:复杂度高等:A修改当前系统模型无法支持,B修改调整新增消息交互流程等,C修改业务判断点15个以上 | E19: 系统作为服务提供方向外部系统提供的接口 A级:涉及业务字段1-10个 B级:涉及业务字段11-30个 C级:涉及业务字段31-60个 D级:涉及业务字段大于60个 | F19: 系统作为服务消费方调用外部系统提供的接口 A级:涉及业务字段1-10个 B级:涉及业务字段11-30个 C级:涉及业务字段31-60个 D级:涉及业务字段大于60个 | G19: 修改提供方接口或消费方接口 A级:涉及业务字段1-10个 B级:涉及业务字段11-30个 C级:涉及业务字段31-60个 D级:涉及业务字段大于60个 | H19: 系统与省份/专业子公司系统的交互接口联调 A级:准实时分钟级接口交互(如文件)，且涉及业务字段1-15个 B级:准实时分钟级接口交互(如文件)，且涉及业务字段大于15个 C级:实时秒级接口交互(如消息)，且涉及业务字段1-10个 D级:实时秒级接口交互(如消息)，且涉及业务字段大于10个 | I19: 配置新的业务或管理流程，包括流程环节定义、流程编排等 A级:配置环节和控制线1-10个 B级:配置环节和控制线11-20个 C级:配置环节和控制线21-30个 D级:配置环节和控制线大于30 | J19: 修改业务或管理流程的配置，包括流程环节定义、流程编排等 A级:配置环节和控制线1-5个 B级:配置环节和控制线6-10个 C级:配置环节和控制线11-20个 D级:配置环节和控制线大于20个 | K19: 以程序开发的方式增加新报表 A级:报表元素1-5个 B级:报表元素在6-10个 C级:报表元素在11-20个 D级:报表元素大于20个 | L19: 以程序开发的方式修改原报表 A级:报表元素1-5个 B级:报表元素在6-10个 C级:报表元素在11-20个 D级:报表元素大于20个 | M19: 使用报表配置工具配置新报表 A级:报表字段1-15个 B级:报表字段16-30个 C级:报表字段31-50个 D级:报表字段50个以上 | N19: 新增导出数据的模板，如导出EXCEL文件数据、PDF文件数据或文本文件数据等 A级:导出信息1-10个 B级:导出信息11个-20个 C级:导出信息21个-30个 D级:导出信息大于30个 | O19: 修改已有导出数据的模板 A级:修改点1-10个 B级:修改点11-20个 C级:修改点21-30个 D级:修改点大于30个 | P19: 新增批量导入数据的功能 A级:基于单张表导入数据简单逻辑 B级:基于单张表导入数据复杂逻辑 C级:基于多张表导入数据简单逻辑 D级:基于多张表导入数据复杂逻辑 | Q19: 修改已有批量导入数据的功能，如导入EXCEL文件数据、文本文件数据等 A级:基于单张表修改导入功能简单逻辑 B级:基于单张表修改导入功能复杂逻辑 C级:基于多张表修改导入功能简单逻辑 D级:基于多张表修改导入功能复杂逻辑 | R19: 根据业务部门临时性的、针对特定需求提供数据 A级:基于单张表直接取数简单逻辑 B级:基于单张表直接取数复杂逻辑 C级:基于多张表直接取数简单逻辑 D级:基于多表直接取数复杂逻辑 | S19: 对数据进行批量修改 A级:基于单张表修改数据，简单逻辑 B级:基于单张表修改数据，复杂逻辑 C级:基于多张表修改数据，简单逻辑 D级:基于多张表修改数据，复杂逻辑 | T19: 配置系统需要的数据，包括业务数据配置、系统数据配置等，如业务规则配置、系统参数配置等 A级:基于单张表配置数据简单逻辑 B级:基于单张表配置数据复杂逻辑 C级:基于多张表配置数据简单逻辑 D级:基于多张表配置数据复杂逻辑 | U19: 根据稽核规则进行数据采集、比对、差异分析等 A级:基于单张表取数稽核简单逻辑 B级:基于单张表取数稽核复杂逻辑 C级:基于多张表取数稽核简单逻辑 D级:基于多张表取数稽核复杂逻辑 | V19: 根据业务需求对数据进行加工处理，如补充数据、拆分数据、合并数据等等 A级:基于单张表进行数据加工，简单逻辑 B级:基于单张表进行数据加工，复杂逻辑 C级:基于多张表进行数据加工，简单逻辑 D级:基于多张表进行数据加工，复杂逻辑 | W19: 根据业务需求进行数据预处理、模型假设、模型设计与实现、模型评估等 A级:基于单张表取数测算简单逻辑 B级:基于单张表取数测算复杂逻辑 C级:基于多张表取数测算简单逻辑 D级:基于多张表取数测算复杂逻辑 | X19: 指因cpu扩容、内存扩容导致的主机配置实施工作 A级:涉及1-10台主机(含虚拟机) B级:涉及11-20台主机(含虚拟机) C级:涉及21-100台主机(含虚拟机) D级:大于100台主机(含虚拟机) | Y19: 指因存储空间扩容导致的配置工作实施工作 A级:1-10台应用主机存储扩容配置 B级:10台以上应用主机存储扩容配置 C级:1-5套物理数据库存储扩容配置 D级:5套以上物理数据库存储扩容配置 | Z19: 指网络参数配置实施工作 A级:网络策略逻辑简单,所需配置网络节点数1-2个 B级:复杂度一般,所需配置网络节点数3-5个 C级:复杂度中等,所需配置网络节点数6-10个 D级:复杂度高等,所需配置网络节点数大于10个 | AA19: 指平台、应用部署实施工作 A级:平台应用部署简单,对相应服务简单部署启动即可 B级:平台应用部署后,单服务参数配置复杂,参数调整在1-5个之间 C级:平台应用存在两种依赖关系或单点登录关系,参数调整在5个以上 D级:部署复杂,需要依赖两个及以上组件,配置参数在10个以上 | AB19: 指对省业务与集团业务进行差异分析的工作,仅适合于全国大集中系统 A级:单系统简单的方案和流程 B级:单系统复杂的方案和流程 C级:多系统跨流程的简单方案和流程 D级:多系统跨流程的复杂方案和流程 | AC19: 指在推广系统上进行系统或业务参数配置的工作,仅适合于全国大集中系统 A级:基于单张表配置数据简单逻辑 B级:基于单张表配置数据复杂逻辑 C级:基于多张表配置数据简单逻辑 D级:基于多张表配置数据复杂逻辑 | AD19: 是指业务的端到端测试工作,仅适合于全国大集中系统 A级:基于单系统简单流程 B级:基于单系统复杂流程 C级:基于多系统简单流程 D级:基于多系统复杂流程 | AE19: 应用软件服务器和终端安装或版本升级,,仅适合于全国大集中系统 A级:平台应用部署简单，对相应服务简单部署启动即可 B级:平台应用部署后，单服务参数配置复杂，参数调整在1-5个之间 C级:平台应用存在两种依赖关系或单点登录关系，并且参数调整在5个以上 D级:部署复杂，需要依赖两个及以上组件，并且配置参数在10个以上 | AF19: 指在生产环境中进行的性能测试工作,仅适合于全国大集中系统 A级:性能测试案例1-5个 B级:性能测试案例6-10个 C级:性能测试案例11-20个 D级:性能测试案例大于20个 | AG19: 指对数据进行脱敏处理的工作,仅适合于全国大集中系统 A级:数据脱敏1-5个字段 B级:数据脱敏6-10个字段 C级:数据脱敏11-15个字段 D级:数据脱敏大于15个字段 | AH19: 指推广中需要的基础数据收集和数据清理工作,仅适合于全国大集中系统 A级:收集与清理1-10个字段 B级:收集与清理11-20个字段 C级:收集与清理21-30个字段 D级:收集与清理大于30个字段 | AI19: 指数据由旧系统迁移到新系统的处理工作,仅适合于全国大集中系统 A级:割接的数据1-25个字段 B级:割接的数据26-50个字段 C级:割接的数据51-75个字段 D级:割接的数据大于75个字段 | AJ19: 指推广中需要的网络配置与验证工作,仅适合于全国大集中系统 A级:网络策略逻辑简单，所需配置网络节点1-2个 B级:复杂度一般，所需配置网络节点数3-5个 C级:复杂度中等，所需配置网络节点数6-10个 D级:复杂度高等，所需配置网络节点数大于10个
A23: 响应速度 | B23: 集成环境复杂性 | C23: 可靠性 | D23: 系统设计容量
A24: 0按业务最高响应速度要求，事务处理耗时无严格要求 | B24: 0采用单机模式 | C24: 0应用系统无可靠性要求 | D24: 0系统设计数据容量10GB以下
A25: 1事务处理响应时间在2小时以上 | B25: 1采用数据库与应用服务分离模式 | C25: 1应用系统采用了双机冷备措施 | D25: 1系统设计数据容量10GB至100GB
A26: 2事务处理响应时间在1-2小时之间 | B26: 2采用了传统集群技术(无采用分布式技术) | C26: 2应用系统采用了双机热备(数据)措施 | D26: 2系统设计数据容量100GB至1TB
A27: 3事务处理响应时间是分钟级的 | B27: 3采用了应用分布式技术 | C27: 3应用系统采用了双机热备(数据+应用)措施 | D27: 3系统设计数据容量1TB至100TB
A28: 4事务处理响应时间是秒级的 | B28: 4采用了数据库分布式技术 | C28: 4应用系统采用了数据异地容灾措施 | D28: 4系统设计数据容量100TB至1000TB
A29: 5事务处理响应时间是毫秒级的 | B29: 5采用了PAAS云技术 | C29: 5应用系统采用了业务异地容灾措施 | D29: 5系统设计数据容量PB以上
